Using selector: EpollSelector
Using selector: EpollSelector
Watching for file changes with StatReloader
Using selector: EpollSelector
Using selector: EpollSelector
Watching for file changes with StatReloader
/mnt/disk1/django/decorator/decorator/settings.py changed, reloading.
Using selector: EpollSelector
Watching for file changes with StatReloader
Using selector: EpollSelector
Using selector: EpollSelector
Using selector: EpollSelector
Watching for file changes with StatReloader
Internal Server Error: /
Traceback (most recent call last):
  File "/mnt/disk1/django/env_decorator/lib/python3.6/site-packages/django/template/defaulttags.py", line 1034, in find_library
    return parser.libraries[name]
KeyError: 'mathfilters'

During handling of the above exception, another exception occurred:

Traceback (most recent call last):
  File "/mnt/disk1/django/env_decorator/lib/python3.6/site-packages/django/core/handlers/exception.py", line 47, in inner
    response = get_response(request)
  File "/mnt/disk1/django/env_decorator/lib/python3.6/site-packages/django/core/handlers/base.py", line 181, in _get_response
    response = wrapped_callback(request, *callback_args, **callback_kwargs)
  File "/mnt/disk1/django/decorator/main/views.py", line 64, in index
    return render(request, 'index.html')
  File "/mnt/disk1/django/env_decorator/lib/python3.6/site-packages/django/shortcuts.py", line 19, in render
    content = loader.render_to_string(template_name, context, request, using=using)
  File "/mnt/disk1/django/env_decorator/lib/python3.6/site-packages/django/template/loader.py", line 61, in render_to_string
    template = get_template(template_name, using=using)
  File "/mnt/disk1/django/env_decorator/lib/python3.6/site-packages/django/template/loader.py", line 15, in get_template
    return engine.get_template(template_name)
  File "/mnt/disk1/django/env_decorator/lib/python3.6/site-packages/django/template/backends/django.py", line 34, in get_template
    return Template(self.engine.get_template(template_name), self)
  File "/mnt/disk1/django/env_decorator/lib/python3.6/site-packages/django/template/engine.py", line 143, in get_template
    template, origin = self.find_template(template_name)
  File "/mnt/disk1/django/env_decorator/lib/python3.6/site-packages/django/template/engine.py", line 125, in find_template
    template = loader.get_template(name, skip=skip)
  File "/mnt/disk1/django/env_decorator/lib/python3.6/site-packages/django/template/loaders/base.py", line 30, in get_template
    contents, origin, origin.template_name, self.engine,
  File "/mnt/disk1/django/env_decorator/lib/python3.6/site-packages/django/template/base.py", line 155, in __init__
    self.nodelist = self.compile_nodelist()
  File "/mnt/disk1/django/env_decorator/lib/python3.6/site-packages/django/template/base.py", line 193, in compile_nodelist
    return parser.parse()
  File "/mnt/disk1/django/env_decorator/lib/python3.6/site-packages/django/template/base.py", line 478, in parse
    raise self.error(token, e)
  File "/mnt/disk1/django/env_decorator/lib/python3.6/site-packages/django/template/base.py", line 476, in parse
    compiled_result = compile_func(self, token)
  File "/mnt/disk1/django/env_decorator/lib/python3.6/site-packages/django/template/loader_tags.py", line 270, in do_extends
    nodelist = parser.parse()
  File "/mnt/disk1/django/env_decorator/lib/python3.6/site-packages/django/template/base.py", line 478, in parse
    raise self.error(token, e)
  File "/mnt/disk1/django/env_decorator/lib/python3.6/site-packages/django/template/base.py", line 476, in parse
    compiled_result = compile_func(self, token)
  File "/mnt/disk1/django/env_decorator/lib/python3.6/site-packages/django/template/defaulttags.py", line 1091, in load
    lib = find_library(parser, name)
  File "/mnt/disk1/django/env_decorator/lib/python3.6/site-packages/django/template/defaulttags.py", line 1038, in find_library
    name, "\n".join(sorted(parser.libraries)),
django.template.exceptions.TemplateSyntaxError: 'mathfilters' is not a registered tag library. Must be one of:
admin_list
admin_modify
admin_urls
cache
i18n
l10n
log
static
tz
Internal Server Error: /
Traceback (most recent call last):
  File "/mnt/disk1/django/env_decorator/lib/python3.6/site-packages/django/template/defaulttags.py", line 1034, in find_library
    return parser.libraries[name]
KeyError: 'main_tags'

During handling of the above exception, another exception occurred:

Traceback (most recent call last):
  File "/mnt/disk1/django/env_decorator/lib/python3.6/site-packages/django/core/handlers/exception.py", line 47, in inner
    response = get_response(request)
  File "/mnt/disk1/django/env_decorator/lib/python3.6/site-packages/django/core/handlers/base.py", line 181, in _get_response
    response = wrapped_callback(request, *callback_args, **callback_kwargs)
  File "/mnt/disk1/django/decorator/main/views.py", line 64, in index
    return render(request, 'index.html')
  File "/mnt/disk1/django/env_decorator/lib/python3.6/site-packages/django/shortcuts.py", line 19, in render
    content = loader.render_to_string(template_name, context, request, using=using)
  File "/mnt/disk1/django/env_decorator/lib/python3.6/site-packages/django/template/loader.py", line 61, in render_to_string
    template = get_template(template_name, using=using)
  File "/mnt/disk1/django/env_decorator/lib/python3.6/site-packages/django/template/loader.py", line 15, in get_template
    return engine.get_template(template_name)
  File "/mnt/disk1/django/env_decorator/lib/python3.6/site-packages/django/template/backends/django.py", line 34, in get_template
    return Template(self.engine.get_template(template_name), self)
  File "/mnt/disk1/django/env_decorator/lib/python3.6/site-packages/django/template/engine.py", line 143, in get_template
    template, origin = self.find_template(template_name)
  File "/mnt/disk1/django/env_decorator/lib/python3.6/site-packages/django/template/engine.py", line 125, in find_template
    template = loader.get_template(name, skip=skip)
  File "/mnt/disk1/django/env_decorator/lib/python3.6/site-packages/django/template/loaders/base.py", line 30, in get_template
    contents, origin, origin.template_name, self.engine,
  File "/mnt/disk1/django/env_decorator/lib/python3.6/site-packages/django/template/base.py", line 155, in __init__
    self.nodelist = self.compile_nodelist()
  File "/mnt/disk1/django/env_decorator/lib/python3.6/site-packages/django/template/base.py", line 193, in compile_nodelist
    return parser.parse()
  File "/mnt/disk1/django/env_decorator/lib/python3.6/site-packages/django/template/base.py", line 478, in parse
    raise self.error(token, e)
  File "/mnt/disk1/django/env_decorator/lib/python3.6/site-packages/django/template/base.py", line 476, in parse
    compiled_result = compile_func(self, token)
  File "/mnt/disk1/django/env_decorator/lib/python3.6/site-packages/django/template/loader_tags.py", line 270, in do_extends
    nodelist = parser.parse()
  File "/mnt/disk1/django/env_decorator/lib/python3.6/site-packages/django/template/base.py", line 478, in parse
    raise self.error(token, e)
  File "/mnt/disk1/django/env_decorator/lib/python3.6/site-packages/django/template/base.py", line 476, in parse
    compiled_result = compile_func(self, token)
  File "/mnt/disk1/django/env_decorator/lib/python3.6/site-packages/django/template/defaulttags.py", line 1091, in load
    lib = find_library(parser, name)
  File "/mnt/disk1/django/env_decorator/lib/python3.6/site-packages/django/template/defaulttags.py", line 1038, in find_library
    name, "\n".join(sorted(parser.libraries)),
django.template.exceptions.TemplateSyntaxError: 'main_tags' is not a registered tag library. Must be one of:
admin_list
admin_modify
admin_urls
cache
i18n
l10n
log
static
tz
Internal Server Error: /
Traceback (most recent call last):
  File "/mnt/disk1/django/env_decorator/lib/python3.6/site-packages/django/core/handlers/exception.py", line 47, in inner
    response = get_response(request)
  File "/mnt/disk1/django/env_decorator/lib/python3.6/site-packages/django/core/handlers/base.py", line 181, in _get_response
    response = wrapped_callback(request, *callback_args, **callback_kwargs)
  File "/mnt/disk1/django/decorator/main/views.py", line 64, in index
    return render(request, 'index.html')
  File "/mnt/disk1/django/env_decorator/lib/python3.6/site-packages/django/shortcuts.py", line 19, in render
    content = loader.render_to_string(template_name, context, request, using=using)
  File "/mnt/disk1/django/env_decorator/lib/python3.6/site-packages/django/template/loader.py", line 61, in render_to_string
    template = get_template(template_name, using=using)
  File "/mnt/disk1/django/env_decorator/lib/python3.6/site-packages/django/template/loader.py", line 15, in get_template
    return engine.get_template(template_name)
  File "/mnt/disk1/django/env_decorator/lib/python3.6/site-packages/django/template/backends/django.py", line 34, in get_template
    return Template(self.engine.get_template(template_name), self)
  File "/mnt/disk1/django/env_decorator/lib/python3.6/site-packages/django/template/engine.py", line 143, in get_template
    template, origin = self.find_template(template_name)
  File "/mnt/disk1/django/env_decorator/lib/python3.6/site-packages/django/template/engine.py", line 125, in find_template
    template = loader.get_template(name, skip=skip)
  File "/mnt/disk1/django/env_decorator/lib/python3.6/site-packages/django/template/loaders/base.py", line 30, in get_template
    contents, origin, origin.template_name, self.engine,
  File "/mnt/disk1/django/env_decorator/lib/python3.6/site-packages/django/template/base.py", line 155, in __init__
    self.nodelist = self.compile_nodelist()
  File "/mnt/disk1/django/env_decorator/lib/python3.6/site-packages/django/template/base.py", line 193, in compile_nodelist
    return parser.parse()
  File "/mnt/disk1/django/env_decorator/lib/python3.6/site-packages/django/template/base.py", line 478, in parse
    raise self.error(token, e)
  File "/mnt/disk1/django/env_decorator/lib/python3.6/site-packages/django/template/base.py", line 476, in parse
    compiled_result = compile_func(self, token)
  File "/mnt/disk1/django/env_decorator/lib/python3.6/site-packages/django/template/loader_tags.py", line 270, in do_extends
    nodelist = parser.parse()
  File "/mnt/disk1/django/env_decorator/lib/python3.6/site-packages/django/template/base.py", line 478, in parse
    raise self.error(token, e)
  File "/mnt/disk1/django/env_decorator/lib/python3.6/site-packages/django/template/base.py", line 476, in parse
    compiled_result = compile_func(self, token)
  File "/mnt/disk1/django/env_decorator/lib/python3.6/site-packages/django/template/loader_tags.py", line 213, in do_block
    nodelist = parser.parse(('endblock',))
  File "/mnt/disk1/django/env_decorator/lib/python3.6/site-packages/django/template/base.py", line 478, in parse
    raise self.error(token, e)
  File "/mnt/disk1/django/env_decorator/lib/python3.6/site-packages/django/template/base.py", line 476, in parse
    compiled_result = compile_func(self, token)
  File "/mnt/disk1/django/env_decorator/lib/python3.6/site-packages/django/template/defaulttags.py", line 814, in do_for
    nodelist_loop = parser.parse(('empty', 'endfor',))
  File "/mnt/disk1/django/env_decorator/lib/python3.6/site-packages/django/template/base.py", line 478, in parse
    raise self.error(token, e)
  File "/mnt/disk1/django/env_decorator/lib/python3.6/site-packages/django/template/base.py", line 476, in parse
    compiled_result = compile_func(self, token)
  File "/mnt/disk1/django/env_decorator/lib/python3.6/site-packages/django/template/defaulttags.py", line 1478, in do_with
    extra_context = token_kwargs(remaining_bits, parser, support_legacy=True)
  File "/mnt/disk1/django/env_decorator/lib/python3.6/site-packages/django/template/base.py", line 1040, in token_kwargs
    kwargs[key] = parser.compile_filter(value)
  File "/mnt/disk1/django/env_decorator/lib/python3.6/site-packages/django/template/base.py", line 563, in compile_filter
    return FilterExpression(token, self)
  File "/mnt/disk1/django/env_decorator/lib/python3.6/site-packages/django/template/base.py", line 657, in __init__
    filter_func = parser.find_filter(filter_name)
  File "/mnt/disk1/django/env_decorator/lib/python3.6/site-packages/django/template/base.py", line 569, in find_filter
    raise TemplateSyntaxError("Invalid filter: '%s'" % filter_name)
django.template.exceptions.TemplateSyntaxError: Invalid filter: 'div'
Internal Server Error: /
Traceback (most recent call last):
  File "/mnt/disk1/django/env_decorator/lib/python3.6/site-packages/django/template/defaulttags.py", line 1034, in find_library
    return parser.libraries[name]
KeyError: 'staticfiles'

During handling of the above exception, another exception occurred:

Traceback (most recent call last):
  File "/mnt/disk1/django/env_decorator/lib/python3.6/site-packages/django/core/handlers/exception.py", line 47, in inner
    response = get_response(request)
  File "/mnt/disk1/django/env_decorator/lib/python3.6/site-packages/django/core/handlers/base.py", line 181, in _get_response
    response = wrapped_callback(request, *callback_args, **callback_kwargs)
  File "/mnt/disk1/django/decorator/main/views.py", line 64, in index
    return render(request, 'index.html')
  File "/mnt/disk1/django/env_decorator/lib/python3.6/site-packages/django/shortcuts.py", line 19, in render
    content = loader.render_to_string(template_name, context, request, using=using)
  File "/mnt/disk1/django/env_decorator/lib/python3.6/site-packages/django/template/loader.py", line 62, in render_to_string
    return template.render(context, request)
  File "/mnt/disk1/django/env_decorator/lib/python3.6/site-packages/django/template/backends/django.py", line 61, in render
    return self.template.render(context)
  File "/mnt/disk1/django/env_decorator/lib/python3.6/site-packages/django/template/base.py", line 170, in render
    return self._render(context)
  File "/mnt/disk1/django/env_decorator/lib/python3.6/site-packages/django/template/base.py", line 162, in _render
    return self.nodelist.render(context)
  File "/mnt/disk1/django/env_decorator/lib/python3.6/site-packages/django/template/base.py", line 938, in render
    bit = node.render_annotated(context)
  File "/mnt/disk1/django/env_decorator/lib/python3.6/site-packages/django/template/base.py", line 905, in render_annotated
    return self.render(context)
  File "/mnt/disk1/django/env_decorator/lib/python3.6/site-packages/django/template/loader_tags.py", line 127, in render
    compiled_parent = self.get_parent(context)
  File "/mnt/disk1/django/env_decorator/lib/python3.6/site-packages/django/template/loader_tags.py", line 124, in get_parent
    return self.find_template(parent, context)
  File "/mnt/disk1/django/env_decorator/lib/python3.6/site-packages/django/template/loader_tags.py", line 104, in find_template
    template_name, skip=history,
  File "/mnt/disk1/django/env_decorator/lib/python3.6/site-packages/django/template/engine.py", line 125, in find_template
    template = loader.get_template(name, skip=skip)
  File "/mnt/disk1/django/env_decorator/lib/python3.6/site-packages/django/template/loaders/base.py", line 30, in get_template
    contents, origin, origin.template_name, self.engine,
  File "/mnt/disk1/django/env_decorator/lib/python3.6/site-packages/django/template/base.py", line 155, in __init__
    self.nodelist = self.compile_nodelist()
  File "/mnt/disk1/django/env_decorator/lib/python3.6/site-packages/django/template/base.py", line 193, in compile_nodelist
    return parser.parse()
  File "/mnt/disk1/django/env_decorator/lib/python3.6/site-packages/django/template/base.py", line 478, in parse
    raise self.error(token, e)
  File "/mnt/disk1/django/env_decorator/lib/python3.6/site-packages/django/template/base.py", line 476, in parse
    compiled_result = compile_func(self, token)
  File "/mnt/disk1/django/env_decorator/lib/python3.6/site-packages/django/template/defaulttags.py", line 1091, in load
    lib = find_library(parser, name)
  File "/mnt/disk1/django/env_decorator/lib/python3.6/site-packages/django/template/defaulttags.py", line 1038, in find_library
    name, "\n".join(sorted(parser.libraries)),
django.template.exceptions.TemplateSyntaxError: 'staticfiles' is not a registered tag library. Must be one of:
admin_list
admin_modify
admin_urls
cache
i18n
l10n
log
static
tz
Internal Server Error: /
Traceback (most recent call last):
  File "/mnt/disk1/django/env_decorator/lib/python3.6/site-packages/django/template/backends/django.py", line 61, in render
    return self.template.render(context)
  File "/mnt/disk1/django/env_decorator/lib/python3.6/site-packages/django/template/base.py", line 170, in render
    return self._render(context)
  File "/mnt/disk1/django/env_decorator/lib/python3.6/site-packages/django/template/base.py", line 162, in _render
    return self.nodelist.render(context)
  File "/mnt/disk1/django/env_decorator/lib/python3.6/site-packages/django/template/base.py", line 938, in render
    bit = node.render_annotated(context)
  File "/mnt/disk1/django/env_decorator/lib/python3.6/site-packages/django/template/base.py", line 905, in render_annotated
    return self.render(context)
  File "/mnt/disk1/django/env_decorator/lib/python3.6/site-packages/django/template/loader_tags.py", line 150, in render
    return compiled_parent._render(context)
  File "/mnt/disk1/django/env_decorator/lib/python3.6/site-packages/django/template/base.py", line 162, in _render
    return self.nodelist.render(context)
  File "/mnt/disk1/django/env_decorator/lib/python3.6/site-packages/django/template/base.py", line 938, in render
    bit = node.render_annotated(context)
  File "/mnt/disk1/django/env_decorator/lib/python3.6/site-packages/django/template/base.py", line 905, in render_annotated
    return self.render(context)
  File "/mnt/disk1/django/env_decorator/lib/python3.6/site-packages/django/template/loader_tags.py", line 62, in render
    result = block.nodelist.render(context)
  File "/mnt/disk1/django/env_decorator/lib/python3.6/site-packages/django/template/base.py", line 938, in render
    bit = node.render_annotated(context)
  File "/mnt/disk1/django/env_decorator/lib/python3.6/site-packages/django/template/base.py", line 905, in render_annotated
    return self.render(context)
  File "/mnt/disk1/django/env_decorator/lib/python3.6/site-packages/django/template/loader_tags.py", line 192, in render
    return template.render(context)
  File "/mnt/disk1/django/env_decorator/lib/python3.6/site-packages/django/template/base.py", line 172, in render
    return self._render(context)
  File "/mnt/disk1/django/env_decorator/lib/python3.6/site-packages/django/template/base.py", line 162, in _render
    return self.nodelist.render(context)
  File "/mnt/disk1/django/env_decorator/lib/python3.6/site-packages/django/template/base.py", line 938, in render
    bit = node.render_annotated(context)
  File "/mnt/disk1/django/env_decorator/lib/python3.6/site-packages/django/template/base.py", line 905, in render_annotated
    return self.render(context)
  File "/mnt/disk1/django/env_decorator/lib/python3.6/site-packages/django/template/loader_tags.py", line 180, in render
    template = context.template.engine.select_template(template_name)
  File "/mnt/disk1/django/env_decorator/lib/python3.6/site-packages/django/template/engine.py", line 180, in select_template
    raise TemplateDoesNotExist(', '.join(not_found))
django.template.exceptions.TemplateDoesNotExist: calc_form.html

The above exception was the direct cause of the following exception:

Traceback (most recent call last):
  File "/mnt/disk1/django/env_decorator/lib/python3.6/site-packages/django/core/handlers/exception.py", line 47, in inner
    response = get_response(request)
  File "/mnt/disk1/django/env_decorator/lib/python3.6/site-packages/django/core/handlers/base.py", line 181, in _get_response
    response = wrapped_callback(request, *callback_args, **callback_kwargs)
  File "/mnt/disk1/django/decorator/main/views.py", line 64, in index
    return render(request, 'index.html')
  File "/mnt/disk1/django/env_decorator/lib/python3.6/site-packages/django/shortcuts.py", line 19, in render
    content = loader.render_to_string(template_name, context, request, using=using)
  File "/mnt/disk1/django/env_decorator/lib/python3.6/site-packages/django/template/loader.py", line 62, in render_to_string
    return template.render(context, request)
  File "/mnt/disk1/django/env_decorator/lib/python3.6/site-packages/django/template/backends/django.py", line 63, in render
    reraise(exc, self.backend)
  File "/mnt/disk1/django/env_decorator/lib/python3.6/site-packages/django/template/backends/django.py", line 84, in reraise
    raise new from exc
django.template.exceptions.TemplateDoesNotExist: calc_form.html
Internal Server Error: /favicon.ico
Traceback (most recent call last):
  File "/mnt/disk1/django/env_decorator/lib/python3.6/site-packages/django/contrib/sites/models.py", line 39, in _get_site_by_request
    SITE_CACHE[host] = self.get(domain__iexact=host)
  File "/mnt/disk1/django/env_decorator/lib/python3.6/site-packages/django/db/models/manager.py", line 85, in manager_method
    return getattr(self.get_queryset(), name)(*args, **kwargs)
  File "/mnt/disk1/django/env_decorator/lib/python3.6/site-packages/django/db/models/query.py", line 431, in get
    self.model._meta.object_name
django.contrib.sites.models.Site.DoesNotExist: Site matching query does not exist.

During handling of the above exception, another exception occurred:

Traceback (most recent call last):
  File "/mnt/disk1/django/env_decorator/lib/python3.6/site-packages/django/core/handlers/exception.py", line 47, in inner
    response = get_response(request)
  File "/mnt/disk1/django/env_decorator/lib/python3.6/site-packages/django/utils/deprecation.py", line 116, in __call__
    response = self.process_response(request, response)
  File "/mnt/disk1/django/env_decorator/lib/python3.6/site-packages/django/contrib/redirects/middleware.py", line 29, in process_response
    current_site = get_current_site(request)
  File "/mnt/disk1/django/env_decorator/lib/python3.6/site-packages/django/contrib/sites/shortcuts.py", line 13, in get_current_site
    return Site.objects.get_current(request)
  File "/mnt/disk1/django/env_decorator/lib/python3.6/site-packages/django/contrib/sites/models.py", line 60, in get_current
    return self._get_site_by_request(request)
  File "/mnt/disk1/django/env_decorator/lib/python3.6/site-packages/django/contrib/sites/models.py", line 45, in _get_site_by_request
    SITE_CACHE[domain] = self.get(domain__iexact=domain)
  File "/mnt/disk1/django/env_decorator/lib/python3.6/site-packages/django/db/models/manager.py", line 85, in manager_method
    return getattr(self.get_queryset(), name)(*args, **kwargs)
  File "/mnt/disk1/django/env_decorator/lib/python3.6/site-packages/django/db/models/query.py", line 431, in get
    self.model._meta.object_name
django.contrib.sites.models.Site.DoesNotExist: Site matching query does not exist.
Internal Server Error: /favicon.ico
Traceback (most recent call last):
  File "/mnt/disk1/django/env_decorator/lib/python3.6/site-packages/django/contrib/sites/models.py", line 39, in _get_site_by_request
    SITE_CACHE[host] = self.get(domain__iexact=host)
  File "/mnt/disk1/django/env_decorator/lib/python3.6/site-packages/django/db/models/manager.py", line 85, in manager_method
    return getattr(self.get_queryset(), name)(*args, **kwargs)
  File "/mnt/disk1/django/env_decorator/lib/python3.6/site-packages/django/db/models/query.py", line 431, in get
    self.model._meta.object_name
django.contrib.sites.models.Site.DoesNotExist: Site matching query does not exist.

During handling of the above exception, another exception occurred:

Traceback (most recent call last):
  File "/mnt/disk1/django/env_decorator/lib/python3.6/site-packages/django/core/handlers/exception.py", line 47, in inner
    response = get_response(request)
  File "/mnt/disk1/django/env_decorator/lib/python3.6/site-packages/django/utils/deprecation.py", line 116, in __call__
    response = self.process_response(request, response)
  File "/mnt/disk1/django/env_decorator/lib/python3.6/site-packages/django/contrib/redirects/middleware.py", line 29, in process_response
    current_site = get_current_site(request)
  File "/mnt/disk1/django/env_decorator/lib/python3.6/site-packages/django/contrib/sites/shortcuts.py", line 13, in get_current_site
    return Site.objects.get_current(request)
  File "/mnt/disk1/django/env_decorator/lib/python3.6/site-packages/django/contrib/sites/models.py", line 60, in get_current
    return self._get_site_by_request(request)
  File "/mnt/disk1/django/env_decorator/lib/python3.6/site-packages/django/contrib/sites/models.py", line 45, in _get_site_by_request
    SITE_CACHE[domain] = self.get(domain__iexact=domain)
  File "/mnt/disk1/django/env_decorator/lib/python3.6/site-packages/django/db/models/manager.py", line 85, in manager_method
    return getattr(self.get_queryset(), name)(*args, **kwargs)
  File "/mnt/disk1/django/env_decorator/lib/python3.6/site-packages/django/db/models/query.py", line 431, in get
    self.model._meta.object_name
django.contrib.sites.models.Site.DoesNotExist: Site matching query does not exist.
Internal Server Error: /favicon.ico
Traceback (most recent call last):
  File "/mnt/disk1/django/env_decorator/lib/python3.6/site-packages/django/contrib/sites/models.py", line 39, in _get_site_by_request
    SITE_CACHE[host] = self.get(domain__iexact=host)
  File "/mnt/disk1/django/env_decorator/lib/python3.6/site-packages/django/db/models/manager.py", line 85, in manager_method
    return getattr(self.get_queryset(), name)(*args, **kwargs)
  File "/mnt/disk1/django/env_decorator/lib/python3.6/site-packages/django/db/models/query.py", line 431, in get
    self.model._meta.object_name
django.contrib.sites.models.Site.DoesNotExist: Site matching query does not exist.

During handling of the above exception, another exception occurred:

Traceback (most recent call last):
  File "/mnt/disk1/django/env_decorator/lib/python3.6/site-packages/django/core/handlers/exception.py", line 47, in inner
    response = get_response(request)
  File "/mnt/disk1/django/env_decorator/lib/python3.6/site-packages/django/utils/deprecation.py", line 116, in __call__
    response = self.process_response(request, response)
  File "/mnt/disk1/django/env_decorator/lib/python3.6/site-packages/django/contrib/redirects/middleware.py", line 29, in process_response
    current_site = get_current_site(request)
  File "/mnt/disk1/django/env_decorator/lib/python3.6/site-packages/django/contrib/sites/shortcuts.py", line 13, in get_current_site
    return Site.objects.get_current(request)
  File "/mnt/disk1/django/env_decorator/lib/python3.6/site-packages/django/contrib/sites/models.py", line 60, in get_current
    return self._get_site_by_request(request)
  File "/mnt/disk1/django/env_decorator/lib/python3.6/site-packages/django/contrib/sites/models.py", line 45, in _get_site_by_request
    SITE_CACHE[domain] = self.get(domain__iexact=domain)
  File "/mnt/disk1/django/env_decorator/lib/python3.6/site-packages/django/db/models/manager.py", line 85, in manager_method
    return getattr(self.get_queryset(), name)(*args, **kwargs)
  File "/mnt/disk1/django/env_decorator/lib/python3.6/site-packages/django/db/models/query.py", line 431, in get
    self.model._meta.object_name
django.contrib.sites.models.Site.DoesNotExist: Site matching query does not exist.
Internal Server Error: /favicon.ico
Traceback (most recent call last):
  File "/mnt/disk1/django/env_decorator/lib/python3.6/site-packages/django/contrib/sites/models.py", line 39, in _get_site_by_request
    SITE_CACHE[host] = self.get(domain__iexact=host)
  File "/mnt/disk1/django/env_decorator/lib/python3.6/site-packages/django/db/models/manager.py", line 85, in manager_method
    return getattr(self.get_queryset(), name)(*args, **kwargs)
  File "/mnt/disk1/django/env_decorator/lib/python3.6/site-packages/django/db/models/query.py", line 431, in get
    self.model._meta.object_name
django.contrib.sites.models.Site.DoesNotExist: Site matching query does not exist.

During handling of the above exception, another exception occurred:

Traceback (most recent call last):
  File "/mnt/disk1/django/env_decorator/lib/python3.6/site-packages/django/core/handlers/exception.py", line 47, in inner
    response = get_response(request)
  File "/mnt/disk1/django/env_decorator/lib/python3.6/site-packages/django/utils/deprecation.py", line 116, in __call__
    response = self.process_response(request, response)
  File "/mnt/disk1/django/env_decorator/lib/python3.6/site-packages/django/contrib/redirects/middleware.py", line 29, in process_response
    current_site = get_current_site(request)
  File "/mnt/disk1/django/env_decorator/lib/python3.6/site-packages/django/contrib/sites/shortcuts.py", line 13, in get_current_site
    return Site.objects.get_current(request)
  File "/mnt/disk1/django/env_decorator/lib/python3.6/site-packages/django/contrib/sites/models.py", line 60, in get_current
    return self._get_site_by_request(request)
  File "/mnt/disk1/django/env_decorator/lib/python3.6/site-packages/django/contrib/sites/models.py", line 45, in _get_site_by_request
    SITE_CACHE[domain] = self.get(domain__iexact=domain)
  File "/mnt/disk1/django/env_decorator/lib/python3.6/site-packages/django/db/models/manager.py", line 85, in manager_method
    return getattr(self.get_queryset(), name)(*args, **kwargs)
  File "/mnt/disk1/django/env_decorator/lib/python3.6/site-packages/django/db/models/query.py", line 431, in get
    self.model._meta.object_name
django.contrib.sites.models.Site.DoesNotExist: Site matching query does not exist.
Internal Server Error: /favicon.ico
Traceback (most recent call last):
  File "/mnt/disk1/django/env_decorator/lib/python3.6/site-packages/django/contrib/sites/models.py", line 39, in _get_site_by_request
    SITE_CACHE[host] = self.get(domain__iexact=host)
  File "/mnt/disk1/django/env_decorator/lib/python3.6/site-packages/django/db/models/manager.py", line 85, in manager_method
    return getattr(self.get_queryset(), name)(*args, **kwargs)
  File "/mnt/disk1/django/env_decorator/lib/python3.6/site-packages/django/db/models/query.py", line 431, in get
    self.model._meta.object_name
django.contrib.sites.models.Site.DoesNotExist: Site matching query does not exist.

During handling of the above exception, another exception occurred:

Traceback (most recent call last):
  File "/mnt/disk1/django/env_decorator/lib/python3.6/site-packages/django/core/handlers/exception.py", line 47, in inner
    response = get_response(request)
  File "/mnt/disk1/django/env_decorator/lib/python3.6/site-packages/django/utils/deprecation.py", line 116, in __call__
    response = self.process_response(request, response)
  File "/mnt/disk1/django/env_decorator/lib/python3.6/site-packages/django/contrib/redirects/middleware.py", line 29, in process_response
    current_site = get_current_site(request)
  File "/mnt/disk1/django/env_decorator/lib/python3.6/site-packages/django/contrib/sites/shortcuts.py", line 13, in get_current_site
    return Site.objects.get_current(request)
  File "/mnt/disk1/django/env_decorator/lib/python3.6/site-packages/django/contrib/sites/models.py", line 60, in get_current
    return self._get_site_by_request(request)
  File "/mnt/disk1/django/env_decorator/lib/python3.6/site-packages/django/contrib/sites/models.py", line 45, in _get_site_by_request
    SITE_CACHE[domain] = self.get(domain__iexact=domain)
  File "/mnt/disk1/django/env_decorator/lib/python3.6/site-packages/django/db/models/manager.py", line 85, in manager_method
    return getattr(self.get_queryset(), name)(*args, **kwargs)
  File "/mnt/disk1/django/env_decorator/lib/python3.6/site-packages/django/db/models/query.py", line 431, in get
    self.model._meta.object_name
django.contrib.sites.models.Site.DoesNotExist: Site matching query does not exist.
Internal Server Error: /favicon.ico
Traceback (most recent call last):
  File "/mnt/disk1/django/env_decorator/lib/python3.6/site-packages/django/contrib/sites/models.py", line 39, in _get_site_by_request
    SITE_CACHE[host] = self.get(domain__iexact=host)
  File "/mnt/disk1/django/env_decorator/lib/python3.6/site-packages/django/db/models/manager.py", line 85, in manager_method
    return getattr(self.get_queryset(), name)(*args, **kwargs)
  File "/mnt/disk1/django/env_decorator/lib/python3.6/site-packages/django/db/models/query.py", line 431, in get
    self.model._meta.object_name
django.contrib.sites.models.Site.DoesNotExist: Site matching query does not exist.

During handling of the above exception, another exception occurred:

Traceback (most recent call last):
  File "/mnt/disk1/django/env_decorator/lib/python3.6/site-packages/django/core/handlers/exception.py", line 47, in inner
    response = get_response(request)
  File "/mnt/disk1/django/env_decorator/lib/python3.6/site-packages/django/utils/deprecation.py", line 116, in __call__
    response = self.process_response(request, response)
  File "/mnt/disk1/django/env_decorator/lib/python3.6/site-packages/django/contrib/redirects/middleware.py", line 29, in process_response
    current_site = get_current_site(request)
  File "/mnt/disk1/django/env_decorator/lib/python3.6/site-packages/django/contrib/sites/shortcuts.py", line 13, in get_current_site
    return Site.objects.get_current(request)
  File "/mnt/disk1/django/env_decorator/lib/python3.6/site-packages/django/contrib/sites/models.py", line 60, in get_current
    return self._get_site_by_request(request)
  File "/mnt/disk1/django/env_decorator/lib/python3.6/site-packages/django/contrib/sites/models.py", line 45, in _get_site_by_request
    SITE_CACHE[domain] = self.get(domain__iexact=domain)
  File "/mnt/disk1/django/env_decorator/lib/python3.6/site-packages/django/db/models/manager.py", line 85, in manager_method
    return getattr(self.get_queryset(), name)(*args, **kwargs)
  File "/mnt/disk1/django/env_decorator/lib/python3.6/site-packages/django/db/models/query.py", line 431, in get
    self.model._meta.object_name
django.contrib.sites.models.Site.DoesNotExist: Site matching query does not exist.
Internal Server Error: /favicon.ico
Traceback (most recent call last):
  File "/mnt/disk1/django/env_decorator/lib/python3.6/site-packages/django/contrib/sites/models.py", line 39, in _get_site_by_request
    SITE_CACHE[host] = self.get(domain__iexact=host)
  File "/mnt/disk1/django/env_decorator/lib/python3.6/site-packages/django/db/models/manager.py", line 85, in manager_method
    return getattr(self.get_queryset(), name)(*args, **kwargs)
  File "/mnt/disk1/django/env_decorator/lib/python3.6/site-packages/django/db/models/query.py", line 431, in get
    self.model._meta.object_name
django.contrib.sites.models.Site.DoesNotExist: Site matching query does not exist.

During handling of the above exception, another exception occurred:

Traceback (most recent call last):
  File "/mnt/disk1/django/env_decorator/lib/python3.6/site-packages/django/core/handlers/exception.py", line 47, in inner
    response = get_response(request)
  File "/mnt/disk1/django/env_decorator/lib/python3.6/site-packages/django/utils/deprecation.py", line 116, in __call__
    response = self.process_response(request, response)
  File "/mnt/disk1/django/env_decorator/lib/python3.6/site-packages/django/contrib/redirects/middleware.py", line 29, in process_response
    current_site = get_current_site(request)
  File "/mnt/disk1/django/env_decorator/lib/python3.6/site-packages/django/contrib/sites/shortcuts.py", line 13, in get_current_site
    return Site.objects.get_current(request)
  File "/mnt/disk1/django/env_decorator/lib/python3.6/site-packages/django/contrib/sites/models.py", line 60, in get_current
    return self._get_site_by_request(request)
  File "/mnt/disk1/django/env_decorator/lib/python3.6/site-packages/django/contrib/sites/models.py", line 45, in _get_site_by_request
    SITE_CACHE[domain] = self.get(domain__iexact=domain)
  File "/mnt/disk1/django/env_decorator/lib/python3.6/site-packages/django/db/models/manager.py", line 85, in manager_method
    return getattr(self.get_queryset(), name)(*args, **kwargs)
  File "/mnt/disk1/django/env_decorator/lib/python3.6/site-packages/django/db/models/query.py", line 431, in get
    self.model._meta.object_name
django.contrib.sites.models.Site.DoesNotExist: Site matching query does not exist.
Internal Server Error: /favicon.ico
Traceback (most recent call last):
  File "/mnt/disk1/django/env_decorator/lib/python3.6/site-packages/django/contrib/sites/models.py", line 39, in _get_site_by_request
    SITE_CACHE[host] = self.get(domain__iexact=host)
  File "/mnt/disk1/django/env_decorator/lib/python3.6/site-packages/django/db/models/manager.py", line 85, in manager_method
    return getattr(self.get_queryset(), name)(*args, **kwargs)
  File "/mnt/disk1/django/env_decorator/lib/python3.6/site-packages/django/db/models/query.py", line 431, in get
    self.model._meta.object_name
django.contrib.sites.models.Site.DoesNotExist: Site matching query does not exist.

During handling of the above exception, another exception occurred:

Traceback (most recent call last):
  File "/mnt/disk1/django/env_decorator/lib/python3.6/site-packages/django/core/handlers/exception.py", line 47, in inner
    response = get_response(request)
  File "/mnt/disk1/django/env_decorator/lib/python3.6/site-packages/django/utils/deprecation.py", line 116, in __call__
    response = self.process_response(request, response)
  File "/mnt/disk1/django/env_decorator/lib/python3.6/site-packages/django/contrib/redirects/middleware.py", line 29, in process_response
    current_site = get_current_site(request)
  File "/mnt/disk1/django/env_decorator/lib/python3.6/site-packages/django/contrib/sites/shortcuts.py", line 13, in get_current_site
    return Site.objects.get_current(request)
  File "/mnt/disk1/django/env_decorator/lib/python3.6/site-packages/django/contrib/sites/models.py", line 60, in get_current
    return self._get_site_by_request(request)
  File "/mnt/disk1/django/env_decorator/lib/python3.6/site-packages/django/contrib/sites/models.py", line 45, in _get_site_by_request
    SITE_CACHE[domain] = self.get(domain__iexact=domain)
  File "/mnt/disk1/django/env_decorator/lib/python3.6/site-packages/django/db/models/manager.py", line 85, in manager_method
    return getattr(self.get_queryset(), name)(*args, **kwargs)
  File "/mnt/disk1/django/env_decorator/lib/python3.6/site-packages/django/db/models/query.py", line 431, in get
    self.model._meta.object_name
django.contrib.sites.models.Site.DoesNotExist: Site matching query does not exist.
Internal Server Error: /favicon.ico
Traceback (most recent call last):
  File "/mnt/disk1/django/env_decorator/lib/python3.6/site-packages/django/contrib/sites/models.py", line 39, in _get_site_by_request
    SITE_CACHE[host] = self.get(domain__iexact=host)
  File "/mnt/disk1/django/env_decorator/lib/python3.6/site-packages/django/db/models/manager.py", line 85, in manager_method
    return getattr(self.get_queryset(), name)(*args, **kwargs)
  File "/mnt/disk1/django/env_decorator/lib/python3.6/site-packages/django/db/models/query.py", line 431, in get
    self.model._meta.object_name
django.contrib.sites.models.Site.DoesNotExist: Site matching query does not exist.

During handling of the above exception, another exception occurred:

Traceback (most recent call last):
  File "/mnt/disk1/django/env_decorator/lib/python3.6/site-packages/django/core/handlers/exception.py", line 47, in inner
    response = get_response(request)
  File "/mnt/disk1/django/env_decorator/lib/python3.6/site-packages/django/utils/deprecation.py", line 116, in __call__
    response = self.process_response(request, response)
  File "/mnt/disk1/django/env_decorator/lib/python3.6/site-packages/django/contrib/redirects/middleware.py", line 29, in process_response
    current_site = get_current_site(request)
  File "/mnt/disk1/django/env_decorator/lib/python3.6/site-packages/django/contrib/sites/shortcuts.py", line 13, in get_current_site
    return Site.objects.get_current(request)
  File "/mnt/disk1/django/env_decorator/lib/python3.6/site-packages/django/contrib/sites/models.py", line 60, in get_current
    return self._get_site_by_request(request)
  File "/mnt/disk1/django/env_decorator/lib/python3.6/site-packages/django/contrib/sites/models.py", line 45, in _get_site_by_request
    SITE_CACHE[domain] = self.get(domain__iexact=domain)
  File "/mnt/disk1/django/env_decorator/lib/python3.6/site-packages/django/db/models/manager.py", line 85, in manager_method
    return getattr(self.get_queryset(), name)(*args, **kwargs)
  File "/mnt/disk1/django/env_decorator/lib/python3.6/site-packages/django/db/models/query.py", line 431, in get
    self.model._meta.object_name
django.contrib.sites.models.Site.DoesNotExist: Site matching query does not exist.
Internal Server Error: /favicon.ico
Traceback (most recent call last):
  File "/mnt/disk1/django/env_decorator/lib/python3.6/site-packages/django/contrib/sites/models.py", line 39, in _get_site_by_request
    SITE_CACHE[host] = self.get(domain__iexact=host)
  File "/mnt/disk1/django/env_decorator/lib/python3.6/site-packages/django/db/models/manager.py", line 85, in manager_method
    return getattr(self.get_queryset(), name)(*args, **kwargs)
  File "/mnt/disk1/django/env_decorator/lib/python3.6/site-packages/django/db/models/query.py", line 431, in get
    self.model._meta.object_name
django.contrib.sites.models.Site.DoesNotExist: Site matching query does not exist.

During handling of the above exception, another exception occurred:

Traceback (most recent call last):
  File "/mnt/disk1/django/env_decorator/lib/python3.6/site-packages/django/core/handlers/exception.py", line 47, in inner
    response = get_response(request)
  File "/mnt/disk1/django/env_decorator/lib/python3.6/site-packages/django/utils/deprecation.py", line 116, in __call__
    response = self.process_response(request, response)
  File "/mnt/disk1/django/env_decorator/lib/python3.6/site-packages/django/contrib/redirects/middleware.py", line 29, in process_response
    current_site = get_current_site(request)
  File "/mnt/disk1/django/env_decorator/lib/python3.6/site-packages/django/contrib/sites/shortcuts.py", line 13, in get_current_site
    return Site.objects.get_current(request)
  File "/mnt/disk1/django/env_decorator/lib/python3.6/site-packages/django/contrib/sites/models.py", line 60, in get_current
    return self._get_site_by_request(request)
  File "/mnt/disk1/django/env_decorator/lib/python3.6/site-packages/django/contrib/sites/models.py", line 45, in _get_site_by_request
    SITE_CACHE[domain] = self.get(domain__iexact=domain)
  File "/mnt/disk1/django/env_decorator/lib/python3.6/site-packages/django/db/models/manager.py", line 85, in manager_method
    return getattr(self.get_queryset(), name)(*args, **kwargs)
  File "/mnt/disk1/django/env_decorator/lib/python3.6/site-packages/django/db/models/query.py", line 431, in get
    self.model._meta.object_name
django.contrib.sites.models.Site.DoesNotExist: Site matching query does not exist.
Internal Server Error: /favicon.ico
Traceback (most recent call last):
  File "/mnt/disk1/django/env_decorator/lib/python3.6/site-packages/django/contrib/sites/models.py", line 39, in _get_site_by_request
    SITE_CACHE[host] = self.get(domain__iexact=host)
  File "/mnt/disk1/django/env_decorator/lib/python3.6/site-packages/django/db/models/manager.py", line 85, in manager_method
    return getattr(self.get_queryset(), name)(*args, **kwargs)
  File "/mnt/disk1/django/env_decorator/lib/python3.6/site-packages/django/db/models/query.py", line 431, in get
    self.model._meta.object_name
django.contrib.sites.models.Site.DoesNotExist: Site matching query does not exist.

During handling of the above exception, another exception occurred:

Traceback (most recent call last):
  File "/mnt/disk1/django/env_decorator/lib/python3.6/site-packages/django/core/handlers/exception.py", line 47, in inner
    response = get_response(request)
  File "/mnt/disk1/django/env_decorator/lib/python3.6/site-packages/django/utils/deprecation.py", line 116, in __call__
    response = self.process_response(request, response)
  File "/mnt/disk1/django/env_decorator/lib/python3.6/site-packages/django/contrib/redirects/middleware.py", line 29, in process_response
    current_site = get_current_site(request)
  File "/mnt/disk1/django/env_decorator/lib/python3.6/site-packages/django/contrib/sites/shortcuts.py", line 13, in get_current_site
    return Site.objects.get_current(request)
  File "/mnt/disk1/django/env_decorator/lib/python3.6/site-packages/django/contrib/sites/models.py", line 60, in get_current
    return self._get_site_by_request(request)
  File "/mnt/disk1/django/env_decorator/lib/python3.6/site-packages/django/contrib/sites/models.py", line 45, in _get_site_by_request
    SITE_CACHE[domain] = self.get(domain__iexact=domain)
  File "/mnt/disk1/django/env_decorator/lib/python3.6/site-packages/django/db/models/manager.py", line 85, in manager_method
    return getattr(self.get_queryset(), name)(*args, **kwargs)
  File "/mnt/disk1/django/env_decorator/lib/python3.6/site-packages/django/db/models/query.py", line 431, in get
    self.model._meta.object_name
django.contrib.sites.models.Site.DoesNotExist: Site matching query does not exist.
Internal Server Error: /favicon.ico
Traceback (most recent call last):
  File "/mnt/disk1/django/env_decorator/lib/python3.6/site-packages/django/contrib/sites/models.py", line 39, in _get_site_by_request
    SITE_CACHE[host] = self.get(domain__iexact=host)
  File "/mnt/disk1/django/env_decorator/lib/python3.6/site-packages/django/db/models/manager.py", line 85, in manager_method
    return getattr(self.get_queryset(), name)(*args, **kwargs)
  File "/mnt/disk1/django/env_decorator/lib/python3.6/site-packages/django/db/models/query.py", line 431, in get
    self.model._meta.object_name
django.contrib.sites.models.Site.DoesNotExist: Site matching query does not exist.

During handling of the above exception, another exception occurred:

Traceback (most recent call last):
  File "/mnt/disk1/django/env_decorator/lib/python3.6/site-packages/django/core/handlers/exception.py", line 47, in inner
    response = get_response(request)
  File "/mnt/disk1/django/env_decorator/lib/python3.6/site-packages/django/utils/deprecation.py", line 116, in __call__
    response = self.process_response(request, response)
  File "/mnt/disk1/django/env_decorator/lib/python3.6/site-packages/django/contrib/redirects/middleware.py", line 29, in process_response
    current_site = get_current_site(request)
  File "/mnt/disk1/django/env_decorator/lib/python3.6/site-packages/django/contrib/sites/shortcuts.py", line 13, in get_current_site
    return Site.objects.get_current(request)
  File "/mnt/disk1/django/env_decorator/lib/python3.6/site-packages/django/contrib/sites/models.py", line 60, in get_current
    return self._get_site_by_request(request)
  File "/mnt/disk1/django/env_decorator/lib/python3.6/site-packages/django/contrib/sites/models.py", line 45, in _get_site_by_request
    SITE_CACHE[domain] = self.get(domain__iexact=domain)
  File "/mnt/disk1/django/env_decorator/lib/python3.6/site-packages/django/db/models/manager.py", line 85, in manager_method
    return getattr(self.get_queryset(), name)(*args, **kwargs)
  File "/mnt/disk1/django/env_decorator/lib/python3.6/site-packages/django/db/models/query.py", line 431, in get
    self.model._meta.object_name
django.contrib.sites.models.Site.DoesNotExist: Site matching query does not exist.
Internal Server Error: /favicon.ico
Traceback (most recent call last):
  File "/mnt/disk1/django/env_decorator/lib/python3.6/site-packages/django/contrib/sites/models.py", line 39, in _get_site_by_request
    SITE_CACHE[host] = self.get(domain__iexact=host)
  File "/mnt/disk1/django/env_decorator/lib/python3.6/site-packages/django/db/models/manager.py", line 85, in manager_method
    return getattr(self.get_queryset(), name)(*args, **kwargs)
  File "/mnt/disk1/django/env_decorator/lib/python3.6/site-packages/django/db/models/query.py", line 431, in get
    self.model._meta.object_name
django.contrib.sites.models.Site.DoesNotExist: Site matching query does not exist.

During handling of the above exception, another exception occurred:

Traceback (most recent call last):
  File "/mnt/disk1/django/env_decorator/lib/python3.6/site-packages/django/core/handlers/exception.py", line 47, in inner
    response = get_response(request)
  File "/mnt/disk1/django/env_decorator/lib/python3.6/site-packages/django/utils/deprecation.py", line 116, in __call__
    response = self.process_response(request, response)
  File "/mnt/disk1/django/env_decorator/lib/python3.6/site-packages/django/contrib/redirects/middleware.py", line 29, in process_response
    current_site = get_current_site(request)
  File "/mnt/disk1/django/env_decorator/lib/python3.6/site-packages/django/contrib/sites/shortcuts.py", line 13, in get_current_site
    return Site.objects.get_current(request)
  File "/mnt/disk1/django/env_decorator/lib/python3.6/site-packages/django/contrib/sites/models.py", line 60, in get_current
    return self._get_site_by_request(request)
  File "/mnt/disk1/django/env_decorator/lib/python3.6/site-packages/django/contrib/sites/models.py", line 45, in _get_site_by_request
    SITE_CACHE[domain] = self.get(domain__iexact=domain)
  File "/mnt/disk1/django/env_decorator/lib/python3.6/site-packages/django/db/models/manager.py", line 85, in manager_method
    return getattr(self.get_queryset(), name)(*args, **kwargs)
  File "/mnt/disk1/django/env_decorator/lib/python3.6/site-packages/django/db/models/query.py", line 431, in get
    self.model._meta.object_name
django.contrib.sites.models.Site.DoesNotExist: Site matching query does not exist.
Internal Server Error: /favicon.ico
Traceback (most recent call last):
  File "/mnt/disk1/django/env_decorator/lib/python3.6/site-packages/django/contrib/sites/models.py", line 39, in _get_site_by_request
    SITE_CACHE[host] = self.get(domain__iexact=host)
  File "/mnt/disk1/django/env_decorator/lib/python3.6/site-packages/django/db/models/manager.py", line 85, in manager_method
    return getattr(self.get_queryset(), name)(*args, **kwargs)
  File "/mnt/disk1/django/env_decorator/lib/python3.6/site-packages/django/db/models/query.py", line 431, in get
    self.model._meta.object_name
django.contrib.sites.models.Site.DoesNotExist: Site matching query does not exist.

During handling of the above exception, another exception occurred:

Traceback (most recent call last):
  File "/mnt/disk1/django/env_decorator/lib/python3.6/site-packages/django/core/handlers/exception.py", line 47, in inner
    response = get_response(request)
  File "/mnt/disk1/django/env_decorator/lib/python3.6/site-packages/django/utils/deprecation.py", line 116, in __call__
    response = self.process_response(request, response)
  File "/mnt/disk1/django/env_decorator/lib/python3.6/site-packages/django/contrib/redirects/middleware.py", line 29, in process_response
    current_site = get_current_site(request)
  File "/mnt/disk1/django/env_decorator/lib/python3.6/site-packages/django/contrib/sites/shortcuts.py", line 13, in get_current_site
    return Site.objects.get_current(request)
  File "/mnt/disk1/django/env_decorator/lib/python3.6/site-packages/django/contrib/sites/models.py", line 60, in get_current
    return self._get_site_by_request(request)
  File "/mnt/disk1/django/env_decorator/lib/python3.6/site-packages/django/contrib/sites/models.py", line 45, in _get_site_by_request
    SITE_CACHE[domain] = self.get(domain__iexact=domain)
  File "/mnt/disk1/django/env_decorator/lib/python3.6/site-packages/django/db/models/manager.py", line 85, in manager_method
    return getattr(self.get_queryset(), name)(*args, **kwargs)
  File "/mnt/disk1/django/env_decorator/lib/python3.6/site-packages/django/db/models/query.py", line 431, in get
    self.model._meta.object_name
django.contrib.sites.models.Site.DoesNotExist: Site matching query does not exist.
Internal Server Error: /favicon.ico
Traceback (most recent call last):
  File "/mnt/disk1/django/env_decorator/lib/python3.6/site-packages/django/contrib/sites/models.py", line 39, in _get_site_by_request
    SITE_CACHE[host] = self.get(domain__iexact=host)
  File "/mnt/disk1/django/env_decorator/lib/python3.6/site-packages/django/db/models/manager.py", line 85, in manager_method
    return getattr(self.get_queryset(), name)(*args, **kwargs)
  File "/mnt/disk1/django/env_decorator/lib/python3.6/site-packages/django/db/models/query.py", line 431, in get
    self.model._meta.object_name
django.contrib.sites.models.Site.DoesNotExist: Site matching query does not exist.

During handling of the above exception, another exception occurred:

Traceback (most recent call last):
  File "/mnt/disk1/django/env_decorator/lib/python3.6/site-packages/django/core/handlers/exception.py", line 47, in inner
    response = get_response(request)
  File "/mnt/disk1/django/env_decorator/lib/python3.6/site-packages/django/utils/deprecation.py", line 116, in __call__
    response = self.process_response(request, response)
  File "/mnt/disk1/django/env_decorator/lib/python3.6/site-packages/django/contrib/redirects/middleware.py", line 29, in process_response
    current_site = get_current_site(request)
  File "/mnt/disk1/django/env_decorator/lib/python3.6/site-packages/django/contrib/sites/shortcuts.py", line 13, in get_current_site
    return Site.objects.get_current(request)
  File "/mnt/disk1/django/env_decorator/lib/python3.6/site-packages/django/contrib/sites/models.py", line 60, in get_current
    return self._get_site_by_request(request)
  File "/mnt/disk1/django/env_decorator/lib/python3.6/site-packages/django/contrib/sites/models.py", line 45, in _get_site_by_request
    SITE_CACHE[domain] = self.get(domain__iexact=domain)
  File "/mnt/disk1/django/env_decorator/lib/python3.6/site-packages/django/db/models/manager.py", line 85, in manager_method
    return getattr(self.get_queryset(), name)(*args, **kwargs)
  File "/mnt/disk1/django/env_decorator/lib/python3.6/site-packages/django/db/models/query.py", line 431, in get
    self.model._meta.object_name
django.contrib.sites.models.Site.DoesNotExist: Site matching query does not exist.
Internal Server Error: /favicon.ico
Traceback (most recent call last):
  File "/mnt/disk1/django/env_decorator/lib/python3.6/site-packages/django/contrib/sites/models.py", line 39, in _get_site_by_request
    SITE_CACHE[host] = self.get(domain__iexact=host)
  File "/mnt/disk1/django/env_decorator/lib/python3.6/site-packages/django/db/models/manager.py", line 85, in manager_method
    return getattr(self.get_queryset(), name)(*args, **kwargs)
  File "/mnt/disk1/django/env_decorator/lib/python3.6/site-packages/django/db/models/query.py", line 431, in get
    self.model._meta.object_name
django.contrib.sites.models.Site.DoesNotExist: Site matching query does not exist.

During handling of the above exception, another exception occurred:

Traceback (most recent call last):
  File "/mnt/disk1/django/env_decorator/lib/python3.6/site-packages/django/core/handlers/exception.py", line 47, in inner
    response = get_response(request)
  File "/mnt/disk1/django/env_decorator/lib/python3.6/site-packages/django/utils/deprecation.py", line 116, in __call__
    response = self.process_response(request, response)
  File "/mnt/disk1/django/env_decorator/lib/python3.6/site-packages/django/contrib/redirects/middleware.py", line 29, in process_response
    current_site = get_current_site(request)
  File "/mnt/disk1/django/env_decorator/lib/python3.6/site-packages/django/contrib/sites/shortcuts.py", line 13, in get_current_site
    return Site.objects.get_current(request)
  File "/mnt/disk1/django/env_decorator/lib/python3.6/site-packages/django/contrib/sites/models.py", line 60, in get_current
    return self._get_site_by_request(request)
  File "/mnt/disk1/django/env_decorator/lib/python3.6/site-packages/django/contrib/sites/models.py", line 45, in _get_site_by_request
    SITE_CACHE[domain] = self.get(domain__iexact=domain)
  File "/mnt/disk1/django/env_decorator/lib/python3.6/site-packages/django/db/models/manager.py", line 85, in manager_method
    return getattr(self.get_queryset(), name)(*args, **kwargs)
  File "/mnt/disk1/django/env_decorator/lib/python3.6/site-packages/django/db/models/query.py", line 431, in get
    self.model._meta.object_name
django.contrib.sites.models.Site.DoesNotExist: Site matching query does not exist.
Internal Server Error: /favicon.ico
Traceback (most recent call last):
  File "/mnt/disk1/django/env_decorator/lib/python3.6/site-packages/django/contrib/sites/models.py", line 39, in _get_site_by_request
    SITE_CACHE[host] = self.get(domain__iexact=host)
  File "/mnt/disk1/django/env_decorator/lib/python3.6/site-packages/django/db/models/manager.py", line 85, in manager_method
    return getattr(self.get_queryset(), name)(*args, **kwargs)
  File "/mnt/disk1/django/env_decorator/lib/python3.6/site-packages/django/db/models/query.py", line 431, in get
    self.model._meta.object_name
django.contrib.sites.models.Site.DoesNotExist: Site matching query does not exist.

During handling of the above exception, another exception occurred:

Traceback (most recent call last):
  File "/mnt/disk1/django/env_decorator/lib/python3.6/site-packages/django/core/handlers/exception.py", line 47, in inner
    response = get_response(request)
  File "/mnt/disk1/django/env_decorator/lib/python3.6/site-packages/django/utils/deprecation.py", line 116, in __call__
    response = self.process_response(request, response)
  File "/mnt/disk1/django/env_decorator/lib/python3.6/site-packages/django/contrib/redirects/middleware.py", line 29, in process_response
    current_site = get_current_site(request)
  File "/mnt/disk1/django/env_decorator/lib/python3.6/site-packages/django/contrib/sites/shortcuts.py", line 13, in get_current_site
    return Site.objects.get_current(request)
  File "/mnt/disk1/django/env_decorator/lib/python3.6/site-packages/django/contrib/sites/models.py", line 60, in get_current
    return self._get_site_by_request(request)
  File "/mnt/disk1/django/env_decorator/lib/python3.6/site-packages/django/contrib/sites/models.py", line 45, in _get_site_by_request
    SITE_CACHE[domain] = self.get(domain__iexact=domain)
  File "/mnt/disk1/django/env_decorator/lib/python3.6/site-packages/django/db/models/manager.py", line 85, in manager_method
    return getattr(self.get_queryset(), name)(*args, **kwargs)
  File "/mnt/disk1/django/env_decorator/lib/python3.6/site-packages/django/db/models/query.py", line 431, in get
    self.model._meta.object_name
django.contrib.sites.models.Site.DoesNotExist: Site matching query does not exist.
Internal Server Error: /favicon.ico
Traceback (most recent call last):
  File "/mnt/disk1/django/env_decorator/lib/python3.6/site-packages/django/contrib/sites/models.py", line 39, in _get_site_by_request
    SITE_CACHE[host] = self.get(domain__iexact=host)
  File "/mnt/disk1/django/env_decorator/lib/python3.6/site-packages/django/db/models/manager.py", line 85, in manager_method
    return getattr(self.get_queryset(), name)(*args, **kwargs)
  File "/mnt/disk1/django/env_decorator/lib/python3.6/site-packages/django/db/models/query.py", line 431, in get
    self.model._meta.object_name
django.contrib.sites.models.Site.DoesNotExist: Site matching query does not exist.

During handling of the above exception, another exception occurred:

Traceback (most recent call last):
  File "/mnt/disk1/django/env_decorator/lib/python3.6/site-packages/django/core/handlers/exception.py", line 47, in inner
    response = get_response(request)
  File "/mnt/disk1/django/env_decorator/lib/python3.6/site-packages/django/utils/deprecation.py", line 116, in __call__
    response = self.process_response(request, response)
  File "/mnt/disk1/django/env_decorator/lib/python3.6/site-packages/django/contrib/redirects/middleware.py", line 29, in process_response
    current_site = get_current_site(request)
  File "/mnt/disk1/django/env_decorator/lib/python3.6/site-packages/django/contrib/sites/shortcuts.py", line 13, in get_current_site
    return Site.objects.get_current(request)
  File "/mnt/disk1/django/env_decorator/lib/python3.6/site-packages/django/contrib/sites/models.py", line 60, in get_current
    return self._get_site_by_request(request)
  File "/mnt/disk1/django/env_decorator/lib/python3.6/site-packages/django/contrib/sites/models.py", line 45, in _get_site_by_request
    SITE_CACHE[domain] = self.get(domain__iexact=domain)
  File "/mnt/disk1/django/env_decorator/lib/python3.6/site-packages/django/db/models/manager.py", line 85, in manager_method
    return getattr(self.get_queryset(), name)(*args, **kwargs)
  File "/mnt/disk1/django/env_decorator/lib/python3.6/site-packages/django/db/models/query.py", line 431, in get
    self.model._meta.object_name
django.contrib.sites.models.Site.DoesNotExist: Site matching query does not exist.
Internal Server Error: /favicon.ico
Traceback (most recent call last):
  File "/mnt/disk1/django/env_decorator/lib/python3.6/site-packages/django/contrib/sites/models.py", line 39, in _get_site_by_request
    SITE_CACHE[host] = self.get(domain__iexact=host)
  File "/mnt/disk1/django/env_decorator/lib/python3.6/site-packages/django/db/models/manager.py", line 85, in manager_method
    return getattr(self.get_queryset(), name)(*args, **kwargs)
  File "/mnt/disk1/django/env_decorator/lib/python3.6/site-packages/django/db/models/query.py", line 431, in get
    self.model._meta.object_name
django.contrib.sites.models.Site.DoesNotExist: Site matching query does not exist.

During handling of the above exception, another exception occurred:

Traceback (most recent call last):
  File "/mnt/disk1/django/env_decorator/lib/python3.6/site-packages/django/core/handlers/exception.py", line 47, in inner
    response = get_response(request)
  File "/mnt/disk1/django/env_decorator/lib/python3.6/site-packages/django/utils/deprecation.py", line 116, in __call__
    response = self.process_response(request, response)
  File "/mnt/disk1/django/env_decorator/lib/python3.6/site-packages/django/contrib/redirects/middleware.py", line 29, in process_response
    current_site = get_current_site(request)
  File "/mnt/disk1/django/env_decorator/lib/python3.6/site-packages/django/contrib/sites/shortcuts.py", line 13, in get_current_site
    return Site.objects.get_current(request)
  File "/mnt/disk1/django/env_decorator/lib/python3.6/site-packages/django/contrib/sites/models.py", line 60, in get_current
    return self._get_site_by_request(request)
  File "/mnt/disk1/django/env_decorator/lib/python3.6/site-packages/django/contrib/sites/models.py", line 45, in _get_site_by_request
    SITE_CACHE[domain] = self.get(domain__iexact=domain)
  File "/mnt/disk1/django/env_decorator/lib/python3.6/site-packages/django/db/models/manager.py", line 85, in manager_method
    return getattr(self.get_queryset(), name)(*args, **kwargs)
  File "/mnt/disk1/django/env_decorator/lib/python3.6/site-packages/django/db/models/query.py", line 431, in get
    self.model._meta.object_name
django.contrib.sites.models.Site.DoesNotExist: Site matching query does not exist.
Internal Server Error: /favicon.ico
Traceback (most recent call last):
  File "/mnt/disk1/django/env_decorator/lib/python3.6/site-packages/django/contrib/sites/models.py", line 39, in _get_site_by_request
    SITE_CACHE[host] = self.get(domain__iexact=host)
  File "/mnt/disk1/django/env_decorator/lib/python3.6/site-packages/django/db/models/manager.py", line 85, in manager_method
    return getattr(self.get_queryset(), name)(*args, **kwargs)
  File "/mnt/disk1/django/env_decorator/lib/python3.6/site-packages/django/db/models/query.py", line 431, in get
    self.model._meta.object_name
django.contrib.sites.models.Site.DoesNotExist: Site matching query does not exist.

During handling of the above exception, another exception occurred:

Traceback (most recent call last):
  File "/mnt/disk1/django/env_decorator/lib/python3.6/site-packages/django/core/handlers/exception.py", line 47, in inner
    response = get_response(request)
  File "/mnt/disk1/django/env_decorator/lib/python3.6/site-packages/django/utils/deprecation.py", line 116, in __call__
    response = self.process_response(request, response)
  File "/mnt/disk1/django/env_decorator/lib/python3.6/site-packages/django/contrib/redirects/middleware.py", line 29, in process_response
    current_site = get_current_site(request)
  File "/mnt/disk1/django/env_decorator/lib/python3.6/site-packages/django/contrib/sites/shortcuts.py", line 13, in get_current_site
    return Site.objects.get_current(request)
  File "/mnt/disk1/django/env_decorator/lib/python3.6/site-packages/django/contrib/sites/models.py", line 60, in get_current
    return self._get_site_by_request(request)
  File "/mnt/disk1/django/env_decorator/lib/python3.6/site-packages/django/contrib/sites/models.py", line 45, in _get_site_by_request
    SITE_CACHE[domain] = self.get(domain__iexact=domain)
  File "/mnt/disk1/django/env_decorator/lib/python3.6/site-packages/django/db/models/manager.py", line 85, in manager_method
    return getattr(self.get_queryset(), name)(*args, **kwargs)
  File "/mnt/disk1/django/env_decorator/lib/python3.6/site-packages/django/db/models/query.py", line 431, in get
    self.model._meta.object_name
django.contrib.sites.models.Site.DoesNotExist: Site matching query does not exist.
Internal Server Error: /favicon.ico
Traceback (most recent call last):
  File "/mnt/disk1/django/env_decorator/lib/python3.6/site-packages/django/contrib/sites/models.py", line 39, in _get_site_by_request
    SITE_CACHE[host] = self.get(domain__iexact=host)
  File "/mnt/disk1/django/env_decorator/lib/python3.6/site-packages/django/db/models/manager.py", line 85, in manager_method
    return getattr(self.get_queryset(), name)(*args, **kwargs)
  File "/mnt/disk1/django/env_decorator/lib/python3.6/site-packages/django/db/models/query.py", line 431, in get
    self.model._meta.object_name
django.contrib.sites.models.Site.DoesNotExist: Site matching query does not exist.

During handling of the above exception, another exception occurred:

Traceback (most recent call last):
  File "/mnt/disk1/django/env_decorator/lib/python3.6/site-packages/django/core/handlers/exception.py", line 47, in inner
    response = get_response(request)
  File "/mnt/disk1/django/env_decorator/lib/python3.6/site-packages/django/utils/deprecation.py", line 116, in __call__
    response = self.process_response(request, response)
  File "/mnt/disk1/django/env_decorator/lib/python3.6/site-packages/django/contrib/redirects/middleware.py", line 29, in process_response
    current_site = get_current_site(request)
  File "/mnt/disk1/django/env_decorator/lib/python3.6/site-packages/django/contrib/sites/shortcuts.py", line 13, in get_current_site
    return Site.objects.get_current(request)
  File "/mnt/disk1/django/env_decorator/lib/python3.6/site-packages/django/contrib/sites/models.py", line 60, in get_current
    return self._get_site_by_request(request)
  File "/mnt/disk1/django/env_decorator/lib/python3.6/site-packages/django/contrib/sites/models.py", line 45, in _get_site_by_request
    SITE_CACHE[domain] = self.get(domain__iexact=domain)
  File "/mnt/disk1/django/env_decorator/lib/python3.6/site-packages/django/db/models/manager.py", line 85, in manager_method
    return getattr(self.get_queryset(), name)(*args, **kwargs)
  File "/mnt/disk1/django/env_decorator/lib/python3.6/site-packages/django/db/models/query.py", line 431, in get
    self.model._meta.object_name
django.contrib.sites.models.Site.DoesNotExist: Site matching query does not exist.
Internal Server Error: /favicon.ico
Traceback (most recent call last):
  File "/mnt/disk1/django/env_decorator/lib/python3.6/site-packages/django/contrib/sites/models.py", line 39, in _get_site_by_request
    SITE_CACHE[host] = self.get(domain__iexact=host)
  File "/mnt/disk1/django/env_decorator/lib/python3.6/site-packages/django/db/models/manager.py", line 85, in manager_method
    return getattr(self.get_queryset(), name)(*args, **kwargs)
  File "/mnt/disk1/django/env_decorator/lib/python3.6/site-packages/django/db/models/query.py", line 431, in get
    self.model._meta.object_name
django.contrib.sites.models.Site.DoesNotExist: Site matching query does not exist.

During handling of the above exception, another exception occurred:

Traceback (most recent call last):
  File "/mnt/disk1/django/env_decorator/lib/python3.6/site-packages/django/core/handlers/exception.py", line 47, in inner
    response = get_response(request)
  File "/mnt/disk1/django/env_decorator/lib/python3.6/site-packages/django/utils/deprecation.py", line 116, in __call__
    response = self.process_response(request, response)
  File "/mnt/disk1/django/env_decorator/lib/python3.6/site-packages/django/contrib/redirects/middleware.py", line 29, in process_response
    current_site = get_current_site(request)
  File "/mnt/disk1/django/env_decorator/lib/python3.6/site-packages/django/contrib/sites/shortcuts.py", line 13, in get_current_site
    return Site.objects.get_current(request)
  File "/mnt/disk1/django/env_decorator/lib/python3.6/site-packages/django/contrib/sites/models.py", line 60, in get_current
    return self._get_site_by_request(request)
  File "/mnt/disk1/django/env_decorator/lib/python3.6/site-packages/django/contrib/sites/models.py", line 45, in _get_site_by_request
    SITE_CACHE[domain] = self.get(domain__iexact=domain)
  File "/mnt/disk1/django/env_decorator/lib/python3.6/site-packages/django/db/models/manager.py", line 85, in manager_method
    return getattr(self.get_queryset(), name)(*args, **kwargs)
  File "/mnt/disk1/django/env_decorator/lib/python3.6/site-packages/django/db/models/query.py", line 431, in get
    self.model._meta.object_name
django.contrib.sites.models.Site.DoesNotExist: Site matching query does not exist.
Internal Server Error: /favicon.ico
Traceback (most recent call last):
  File "/mnt/disk1/django/env_decorator/lib/python3.6/site-packages/django/contrib/sites/models.py", line 39, in _get_site_by_request
    SITE_CACHE[host] = self.get(domain__iexact=host)
  File "/mnt/disk1/django/env_decorator/lib/python3.6/site-packages/django/db/models/manager.py", line 85, in manager_method
    return getattr(self.get_queryset(), name)(*args, **kwargs)
  File "/mnt/disk1/django/env_decorator/lib/python3.6/site-packages/django/db/models/query.py", line 431, in get
    self.model._meta.object_name
django.contrib.sites.models.Site.DoesNotExist: Site matching query does not exist.

During handling of the above exception, another exception occurred:

Traceback (most recent call last):
  File "/mnt/disk1/django/env_decorator/lib/python3.6/site-packages/django/core/handlers/exception.py", line 47, in inner
    response = get_response(request)
  File "/mnt/disk1/django/env_decorator/lib/python3.6/site-packages/django/utils/deprecation.py", line 116, in __call__
    response = self.process_response(request, response)
  File "/mnt/disk1/django/env_decorator/lib/python3.6/site-packages/django/contrib/redirects/middleware.py", line 29, in process_response
    current_site = get_current_site(request)
  File "/mnt/disk1/django/env_decorator/lib/python3.6/site-packages/django/contrib/sites/shortcuts.py", line 13, in get_current_site
    return Site.objects.get_current(request)
  File "/mnt/disk1/django/env_decorator/lib/python3.6/site-packages/django/contrib/sites/models.py", line 60, in get_current
    return self._get_site_by_request(request)
  File "/mnt/disk1/django/env_decorator/lib/python3.6/site-packages/django/contrib/sites/models.py", line 45, in _get_site_by_request
    SITE_CACHE[domain] = self.get(domain__iexact=domain)
  File "/mnt/disk1/django/env_decorator/lib/python3.6/site-packages/django/db/models/manager.py", line 85, in manager_method
    return getattr(self.get_queryset(), name)(*args, **kwargs)
  File "/mnt/disk1/django/env_decorator/lib/python3.6/site-packages/django/db/models/query.py", line 431, in get
    self.model._meta.object_name
django.contrib.sites.models.Site.DoesNotExist: Site matching query does not exist.
Internal Server Error: /favicon.ico
Traceback (most recent call last):
  File "/mnt/disk1/django/env_decorator/lib/python3.6/site-packages/django/contrib/sites/models.py", line 39, in _get_site_by_request
    SITE_CACHE[host] = self.get(domain__iexact=host)
  File "/mnt/disk1/django/env_decorator/lib/python3.6/site-packages/django/db/models/manager.py", line 85, in manager_method
    return getattr(self.get_queryset(), name)(*args, **kwargs)
  File "/mnt/disk1/django/env_decorator/lib/python3.6/site-packages/django/db/models/query.py", line 431, in get
    self.model._meta.object_name
django.contrib.sites.models.Site.DoesNotExist: Site matching query does not exist.

During handling of the above exception, another exception occurred:

Traceback (most recent call last):
  File "/mnt/disk1/django/env_decorator/lib/python3.6/site-packages/django/core/handlers/exception.py", line 47, in inner
    response = get_response(request)
  File "/mnt/disk1/django/env_decorator/lib/python3.6/site-packages/django/utils/deprecation.py", line 116, in __call__
    response = self.process_response(request, response)
  File "/mnt/disk1/django/env_decorator/lib/python3.6/site-packages/django/contrib/redirects/middleware.py", line 29, in process_response
    current_site = get_current_site(request)
  File "/mnt/disk1/django/env_decorator/lib/python3.6/site-packages/django/contrib/sites/shortcuts.py", line 13, in get_current_site
    return Site.objects.get_current(request)
  File "/mnt/disk1/django/env_decorator/lib/python3.6/site-packages/django/contrib/sites/models.py", line 60, in get_current
    return self._get_site_by_request(request)
  File "/mnt/disk1/django/env_decorator/lib/python3.6/site-packages/django/contrib/sites/models.py", line 45, in _get_site_by_request
    SITE_CACHE[domain] = self.get(domain__iexact=domain)
  File "/mnt/disk1/django/env_decorator/lib/python3.6/site-packages/django/db/models/manager.py", line 85, in manager_method
    return getattr(self.get_queryset(), name)(*args, **kwargs)
  File "/mnt/disk1/django/env_decorator/lib/python3.6/site-packages/django/db/models/query.py", line 431, in get
    self.model._meta.object_name
django.contrib.sites.models.Site.DoesNotExist: Site matching query does not exist.
Internal Server Error: /favicon.ico
Traceback (most recent call last):
  File "/mnt/disk1/django/env_decorator/lib/python3.6/site-packages/django/contrib/sites/models.py", line 39, in _get_site_by_request
    SITE_CACHE[host] = self.get(domain__iexact=host)
  File "/mnt/disk1/django/env_decorator/lib/python3.6/site-packages/django/db/models/manager.py", line 85, in manager_method
    return getattr(self.get_queryset(), name)(*args, **kwargs)
  File "/mnt/disk1/django/env_decorator/lib/python3.6/site-packages/django/db/models/query.py", line 431, in get
    self.model._meta.object_name
django.contrib.sites.models.Site.DoesNotExist: Site matching query does not exist.

During handling of the above exception, another exception occurred:

Traceback (most recent call last):
  File "/mnt/disk1/django/env_decorator/lib/python3.6/site-packages/django/core/handlers/exception.py", line 47, in inner
    response = get_response(request)
  File "/mnt/disk1/django/env_decorator/lib/python3.6/site-packages/django/utils/deprecation.py", line 116, in __call__
    response = self.process_response(request, response)
  File "/mnt/disk1/django/env_decorator/lib/python3.6/site-packages/django/contrib/redirects/middleware.py", line 29, in process_response
    current_site = get_current_site(request)
  File "/mnt/disk1/django/env_decorator/lib/python3.6/site-packages/django/contrib/sites/shortcuts.py", line 13, in get_current_site
    return Site.objects.get_current(request)
  File "/mnt/disk1/django/env_decorator/lib/python3.6/site-packages/django/contrib/sites/models.py", line 60, in get_current
    return self._get_site_by_request(request)
  File "/mnt/disk1/django/env_decorator/lib/python3.6/site-packages/django/contrib/sites/models.py", line 45, in _get_site_by_request
    SITE_CACHE[domain] = self.get(domain__iexact=domain)
  File "/mnt/disk1/django/env_decorator/lib/python3.6/site-packages/django/db/models/manager.py", line 85, in manager_method
    return getattr(self.get_queryset(), name)(*args, **kwargs)
  File "/mnt/disk1/django/env_decorator/lib/python3.6/site-packages/django/db/models/query.py", line 431, in get
    self.model._meta.object_name
django.contrib.sites.models.Site.DoesNotExist: Site matching query does not exist.
Internal Server Error: /favicon.ico
Traceback (most recent call last):
  File "/mnt/disk1/django/env_decorator/lib/python3.6/site-packages/django/contrib/sites/models.py", line 39, in _get_site_by_request
    SITE_CACHE[host] = self.get(domain__iexact=host)
  File "/mnt/disk1/django/env_decorator/lib/python3.6/site-packages/django/db/models/manager.py", line 85, in manager_method
    return getattr(self.get_queryset(), name)(*args, **kwargs)
  File "/mnt/disk1/django/env_decorator/lib/python3.6/site-packages/django/db/models/query.py", line 431, in get
    self.model._meta.object_name
django.contrib.sites.models.Site.DoesNotExist: Site matching query does not exist.

During handling of the above exception, another exception occurred:

Traceback (most recent call last):
  File "/mnt/disk1/django/env_decorator/lib/python3.6/site-packages/django/core/handlers/exception.py", line 47, in inner
    response = get_response(request)
  File "/mnt/disk1/django/env_decorator/lib/python3.6/site-packages/django/utils/deprecation.py", line 116, in __call__
    response = self.process_response(request, response)
  File "/mnt/disk1/django/env_decorator/lib/python3.6/site-packages/django/contrib/redirects/middleware.py", line 29, in process_response
    current_site = get_current_site(request)
  File "/mnt/disk1/django/env_decorator/lib/python3.6/site-packages/django/contrib/sites/shortcuts.py", line 13, in get_current_site
    return Site.objects.get_current(request)
  File "/mnt/disk1/django/env_decorator/lib/python3.6/site-packages/django/contrib/sites/models.py", line 60, in get_current
    return self._get_site_by_request(request)
  File "/mnt/disk1/django/env_decorator/lib/python3.6/site-packages/django/contrib/sites/models.py", line 45, in _get_site_by_request
    SITE_CACHE[domain] = self.get(domain__iexact=domain)
  File "/mnt/disk1/django/env_decorator/lib/python3.6/site-packages/django/db/models/manager.py", line 85, in manager_method
    return getattr(self.get_queryset(), name)(*args, **kwargs)
  File "/mnt/disk1/django/env_decorator/lib/python3.6/site-packages/django/db/models/query.py", line 431, in get
    self.model._meta.object_name
django.contrib.sites.models.Site.DoesNotExist: Site matching query does not exist.
Internal Server Error: /favicon.ico
Traceback (most recent call last):
  File "/mnt/disk1/django/env_decorator/lib/python3.6/site-packages/django/contrib/sites/models.py", line 39, in _get_site_by_request
    SITE_CACHE[host] = self.get(domain__iexact=host)
  File "/mnt/disk1/django/env_decorator/lib/python3.6/site-packages/django/db/models/manager.py", line 85, in manager_method
    return getattr(self.get_queryset(), name)(*args, **kwargs)
  File "/mnt/disk1/django/env_decorator/lib/python3.6/site-packages/django/db/models/query.py", line 431, in get
    self.model._meta.object_name
django.contrib.sites.models.Site.DoesNotExist: Site matching query does not exist.

During handling of the above exception, another exception occurred:

Traceback (most recent call last):
  File "/mnt/disk1/django/env_decorator/lib/python3.6/site-packages/django/core/handlers/exception.py", line 47, in inner
    response = get_response(request)
  File "/mnt/disk1/django/env_decorator/lib/python3.6/site-packages/django/utils/deprecation.py", line 116, in __call__
    response = self.process_response(request, response)
  File "/mnt/disk1/django/env_decorator/lib/python3.6/site-packages/django/contrib/redirects/middleware.py", line 29, in process_response
    current_site = get_current_site(request)
  File "/mnt/disk1/django/env_decorator/lib/python3.6/site-packages/django/contrib/sites/shortcuts.py", line 13, in get_current_site
    return Site.objects.get_current(request)
  File "/mnt/disk1/django/env_decorator/lib/python3.6/site-packages/django/contrib/sites/models.py", line 60, in get_current
    return self._get_site_by_request(request)
  File "/mnt/disk1/django/env_decorator/lib/python3.6/site-packages/django/contrib/sites/models.py", line 45, in _get_site_by_request
    SITE_CACHE[domain] = self.get(domain__iexact=domain)
  File "/mnt/disk1/django/env_decorator/lib/python3.6/site-packages/django/db/models/manager.py", line 85, in manager_method
    return getattr(self.get_queryset(), name)(*args, **kwargs)
  File "/mnt/disk1/django/env_decorator/lib/python3.6/site-packages/django/db/models/query.py", line 431, in get
    self.model._meta.object_name
django.contrib.sites.models.Site.DoesNotExist: Site matching query does not exist.
Internal Server Error: /favicon.ico
Traceback (most recent call last):
  File "/mnt/disk1/django/env_decorator/lib/python3.6/site-packages/django/contrib/sites/models.py", line 39, in _get_site_by_request
    SITE_CACHE[host] = self.get(domain__iexact=host)
  File "/mnt/disk1/django/env_decorator/lib/python3.6/site-packages/django/db/models/manager.py", line 85, in manager_method
    return getattr(self.get_queryset(), name)(*args, **kwargs)
  File "/mnt/disk1/django/env_decorator/lib/python3.6/site-packages/django/db/models/query.py", line 431, in get
    self.model._meta.object_name
django.contrib.sites.models.Site.DoesNotExist: Site matching query does not exist.

During handling of the above exception, another exception occurred:

Traceback (most recent call last):
  File "/mnt/disk1/django/env_decorator/lib/python3.6/site-packages/django/core/handlers/exception.py", line 47, in inner
    response = get_response(request)
  File "/mnt/disk1/django/env_decorator/lib/python3.6/site-packages/django/utils/deprecation.py", line 116, in __call__
    response = self.process_response(request, response)
  File "/mnt/disk1/django/env_decorator/lib/python3.6/site-packages/django/contrib/redirects/middleware.py", line 29, in process_response
    current_site = get_current_site(request)
  File "/mnt/disk1/django/env_decorator/lib/python3.6/site-packages/django/contrib/sites/shortcuts.py", line 13, in get_current_site
    return Site.objects.get_current(request)
  File "/mnt/disk1/django/env_decorator/lib/python3.6/site-packages/django/contrib/sites/models.py", line 60, in get_current
    return self._get_site_by_request(request)
  File "/mnt/disk1/django/env_decorator/lib/python3.6/site-packages/django/contrib/sites/models.py", line 45, in _get_site_by_request
    SITE_CACHE[domain] = self.get(domain__iexact=domain)
  File "/mnt/disk1/django/env_decorator/lib/python3.6/site-packages/django/db/models/manager.py", line 85, in manager_method
    return getattr(self.get_queryset(), name)(*args, **kwargs)
  File "/mnt/disk1/django/env_decorator/lib/python3.6/site-packages/django/db/models/query.py", line 431, in get
    self.model._meta.object_name
django.contrib.sites.models.Site.DoesNotExist: Site matching query does not exist.
Internal Server Error: /favicon.ico
Traceback (most recent call last):
  File "/mnt/disk1/django/env_decorator/lib/python3.6/site-packages/django/contrib/sites/models.py", line 39, in _get_site_by_request
    SITE_CACHE[host] = self.get(domain__iexact=host)
  File "/mnt/disk1/django/env_decorator/lib/python3.6/site-packages/django/db/models/manager.py", line 85, in manager_method
    return getattr(self.get_queryset(), name)(*args, **kwargs)
  File "/mnt/disk1/django/env_decorator/lib/python3.6/site-packages/django/db/models/query.py", line 431, in get
    self.model._meta.object_name
django.contrib.sites.models.Site.DoesNotExist: Site matching query does not exist.

During handling of the above exception, another exception occurred:

Traceback (most recent call last):
  File "/mnt/disk1/django/env_decorator/lib/python3.6/site-packages/django/core/handlers/exception.py", line 47, in inner
    response = get_response(request)
  File "/mnt/disk1/django/env_decorator/lib/python3.6/site-packages/django/utils/deprecation.py", line 116, in __call__
    response = self.process_response(request, response)
  File "/mnt/disk1/django/env_decorator/lib/python3.6/site-packages/django/contrib/redirects/middleware.py", line 29, in process_response
    current_site = get_current_site(request)
  File "/mnt/disk1/django/env_decorator/lib/python3.6/site-packages/django/contrib/sites/shortcuts.py", line 13, in get_current_site
    return Site.objects.get_current(request)
  File "/mnt/disk1/django/env_decorator/lib/python3.6/site-packages/django/contrib/sites/models.py", line 60, in get_current
    return self._get_site_by_request(request)
  File "/mnt/disk1/django/env_decorator/lib/python3.6/site-packages/django/contrib/sites/models.py", line 45, in _get_site_by_request
    SITE_CACHE[domain] = self.get(domain__iexact=domain)
  File "/mnt/disk1/django/env_decorator/lib/python3.6/site-packages/django/db/models/manager.py", line 85, in manager_method
    return getattr(self.get_queryset(), name)(*args, **kwargs)
  File "/mnt/disk1/django/env_decorator/lib/python3.6/site-packages/django/db/models/query.py", line 431, in get
    self.model._meta.object_name
django.contrib.sites.models.Site.DoesNotExist: Site matching query does not exist.
Internal Server Error: /favicon.ico
Traceback (most recent call last):
  File "/mnt/disk1/django/env_decorator/lib/python3.6/site-packages/django/contrib/sites/models.py", line 39, in _get_site_by_request
    SITE_CACHE[host] = self.get(domain__iexact=host)
  File "/mnt/disk1/django/env_decorator/lib/python3.6/site-packages/django/db/models/manager.py", line 85, in manager_method
    return getattr(self.get_queryset(), name)(*args, **kwargs)
  File "/mnt/disk1/django/env_decorator/lib/python3.6/site-packages/django/db/models/query.py", line 431, in get
    self.model._meta.object_name
django.contrib.sites.models.Site.DoesNotExist: Site matching query does not exist.

During handling of the above exception, another exception occurred:

Traceback (most recent call last):
  File "/mnt/disk1/django/env_decorator/lib/python3.6/site-packages/django/core/handlers/exception.py", line 47, in inner
    response = get_response(request)
  File "/mnt/disk1/django/env_decorator/lib/python3.6/site-packages/django/utils/deprecation.py", line 116, in __call__
    response = self.process_response(request, response)
  File "/mnt/disk1/django/env_decorator/lib/python3.6/site-packages/django/contrib/redirects/middleware.py", line 29, in process_response
    current_site = get_current_site(request)
  File "/mnt/disk1/django/env_decorator/lib/python3.6/site-packages/django/contrib/sites/shortcuts.py", line 13, in get_current_site
    return Site.objects.get_current(request)
  File "/mnt/disk1/django/env_decorator/lib/python3.6/site-packages/django/contrib/sites/models.py", line 60, in get_current
    return self._get_site_by_request(request)
  File "/mnt/disk1/django/env_decorator/lib/python3.6/site-packages/django/contrib/sites/models.py", line 45, in _get_site_by_request
    SITE_CACHE[domain] = self.get(domain__iexact=domain)
  File "/mnt/disk1/django/env_decorator/lib/python3.6/site-packages/django/db/models/manager.py", line 85, in manager_method
    return getattr(self.get_queryset(), name)(*args, **kwargs)
  File "/mnt/disk1/django/env_decorator/lib/python3.6/site-packages/django/db/models/query.py", line 431, in get
    self.model._meta.object_name
django.contrib.sites.models.Site.DoesNotExist: Site matching query does not exist.
Internal Server Error: /favicon.ico
Traceback (most recent call last):
  File "/mnt/disk1/django/env_decorator/lib/python3.6/site-packages/django/contrib/sites/models.py", line 39, in _get_site_by_request
    SITE_CACHE[host] = self.get(domain__iexact=host)
  File "/mnt/disk1/django/env_decorator/lib/python3.6/site-packages/django/db/models/manager.py", line 85, in manager_method
    return getattr(self.get_queryset(), name)(*args, **kwargs)
  File "/mnt/disk1/django/env_decorator/lib/python3.6/site-packages/django/db/models/query.py", line 431, in get
    self.model._meta.object_name
django.contrib.sites.models.Site.DoesNotExist: Site matching query does not exist.

During handling of the above exception, another exception occurred:

Traceback (most recent call last):
  File "/mnt/disk1/django/env_decorator/lib/python3.6/site-packages/django/core/handlers/exception.py", line 47, in inner
    response = get_response(request)
  File "/mnt/disk1/django/env_decorator/lib/python3.6/site-packages/django/utils/deprecation.py", line 116, in __call__
    response = self.process_response(request, response)
  File "/mnt/disk1/django/env_decorator/lib/python3.6/site-packages/django/contrib/redirects/middleware.py", line 29, in process_response
    current_site = get_current_site(request)
  File "/mnt/disk1/django/env_decorator/lib/python3.6/site-packages/django/contrib/sites/shortcuts.py", line 13, in get_current_site
    return Site.objects.get_current(request)
  File "/mnt/disk1/django/env_decorator/lib/python3.6/site-packages/django/contrib/sites/models.py", line 60, in get_current
    return self._get_site_by_request(request)
  File "/mnt/disk1/django/env_decorator/lib/python3.6/site-packages/django/contrib/sites/models.py", line 45, in _get_site_by_request
    SITE_CACHE[domain] = self.get(domain__iexact=domain)
  File "/mnt/disk1/django/env_decorator/lib/python3.6/site-packages/django/db/models/manager.py", line 85, in manager_method
    return getattr(self.get_queryset(), name)(*args, **kwargs)
  File "/mnt/disk1/django/env_decorator/lib/python3.6/site-packages/django/db/models/query.py", line 431, in get
    self.model._meta.object_name
django.contrib.sites.models.Site.DoesNotExist: Site matching query does not exist.
Internal Server Error: /favicon.ico
Traceback (most recent call last):
  File "/mnt/disk1/django/env_decorator/lib/python3.6/site-packages/django/contrib/sites/models.py", line 39, in _get_site_by_request
    SITE_CACHE[host] = self.get(domain__iexact=host)
  File "/mnt/disk1/django/env_decorator/lib/python3.6/site-packages/django/db/models/manager.py", line 85, in manager_method
    return getattr(self.get_queryset(), name)(*args, **kwargs)
  File "/mnt/disk1/django/env_decorator/lib/python3.6/site-packages/django/db/models/query.py", line 431, in get
    self.model._meta.object_name
django.contrib.sites.models.Site.DoesNotExist: Site matching query does not exist.

During handling of the above exception, another exception occurred:

Traceback (most recent call last):
  File "/mnt/disk1/django/env_decorator/lib/python3.6/site-packages/django/core/handlers/exception.py", line 47, in inner
    response = get_response(request)
  File "/mnt/disk1/django/env_decorator/lib/python3.6/site-packages/django/utils/deprecation.py", line 116, in __call__
    response = self.process_response(request, response)
  File "/mnt/disk1/django/env_decorator/lib/python3.6/site-packages/django/contrib/redirects/middleware.py", line 29, in process_response
    current_site = get_current_site(request)
  File "/mnt/disk1/django/env_decorator/lib/python3.6/site-packages/django/contrib/sites/shortcuts.py", line 13, in get_current_site
    return Site.objects.get_current(request)
  File "/mnt/disk1/django/env_decorator/lib/python3.6/site-packages/django/contrib/sites/models.py", line 60, in get_current
    return self._get_site_by_request(request)
  File "/mnt/disk1/django/env_decorator/lib/python3.6/site-packages/django/contrib/sites/models.py", line 45, in _get_site_by_request
    SITE_CACHE[domain] = self.get(domain__iexact=domain)
  File "/mnt/disk1/django/env_decorator/lib/python3.6/site-packages/django/db/models/manager.py", line 85, in manager_method
    return getattr(self.get_queryset(), name)(*args, **kwargs)
  File "/mnt/disk1/django/env_decorator/lib/python3.6/site-packages/django/db/models/query.py", line 431, in get
    self.model._meta.object_name
django.contrib.sites.models.Site.DoesNotExist: Site matching query does not exist.
Internal Server Error: /favicon.ico
Traceback (most recent call last):
  File "/mnt/disk1/django/env_decorator/lib/python3.6/site-packages/django/contrib/sites/models.py", line 39, in _get_site_by_request
    SITE_CACHE[host] = self.get(domain__iexact=host)
  File "/mnt/disk1/django/env_decorator/lib/python3.6/site-packages/django/db/models/manager.py", line 85, in manager_method
    return getattr(self.get_queryset(), name)(*args, **kwargs)
  File "/mnt/disk1/django/env_decorator/lib/python3.6/site-packages/django/db/models/query.py", line 431, in get
    self.model._meta.object_name
django.contrib.sites.models.Site.DoesNotExist: Site matching query does not exist.

During handling of the above exception, another exception occurred:

Traceback (most recent call last):
  File "/mnt/disk1/django/env_decorator/lib/python3.6/site-packages/django/core/handlers/exception.py", line 47, in inner
    response = get_response(request)
  File "/mnt/disk1/django/env_decorator/lib/python3.6/site-packages/django/utils/deprecation.py", line 116, in __call__
    response = self.process_response(request, response)
  File "/mnt/disk1/django/env_decorator/lib/python3.6/site-packages/django/contrib/redirects/middleware.py", line 29, in process_response
    current_site = get_current_site(request)
  File "/mnt/disk1/django/env_decorator/lib/python3.6/site-packages/django/contrib/sites/shortcuts.py", line 13, in get_current_site
    return Site.objects.get_current(request)
  File "/mnt/disk1/django/env_decorator/lib/python3.6/site-packages/django/contrib/sites/models.py", line 60, in get_current
    return self._get_site_by_request(request)
  File "/mnt/disk1/django/env_decorator/lib/python3.6/site-packages/django/contrib/sites/models.py", line 45, in _get_site_by_request
    SITE_CACHE[domain] = self.get(domain__iexact=domain)
  File "/mnt/disk1/django/env_decorator/lib/python3.6/site-packages/django/db/models/manager.py", line 85, in manager_method
    return getattr(self.get_queryset(), name)(*args, **kwargs)
  File "/mnt/disk1/django/env_decorator/lib/python3.6/site-packages/django/db/models/query.py", line 431, in get
    self.model._meta.object_name
django.contrib.sites.models.Site.DoesNotExist: Site matching query does not exist.
/mnt/disk1/django/decorator/main/admin.py changed, reloading.
Using selector: EpollSelector
Watching for file changes with StatReloader
Using selector: EpollSelector
Using selector: EpollSelector
Using selector: EpollSelector
Using selector: EpollSelector
Using selector: EpollSelector
Using selector: EpollSelector
Watching for file changes with StatReloader
Internal Server Error: /favicon.ico
Traceback (most recent call last):
  File "/mnt/disk1/django/env_decorator/lib/python3.6/site-packages/django/contrib/sites/models.py", line 39, in _get_site_by_request
    SITE_CACHE[host] = self.get(domain__iexact=host)
  File "/mnt/disk1/django/env_decorator/lib/python3.6/site-packages/django/db/models/manager.py", line 85, in manager_method
    return getattr(self.get_queryset(), name)(*args, **kwargs)
  File "/mnt/disk1/django/env_decorator/lib/python3.6/site-packages/django/db/models/query.py", line 431, in get
    self.model._meta.object_name
django.contrib.sites.models.Site.DoesNotExist: Site matching query does not exist.

During handling of the above exception, another exception occurred:

Traceback (most recent call last):
  File "/mnt/disk1/django/env_decorator/lib/python3.6/site-packages/django/core/handlers/exception.py", line 47, in inner
    response = get_response(request)
  File "/mnt/disk1/django/env_decorator/lib/python3.6/site-packages/django/utils/deprecation.py", line 116, in __call__
    response = self.process_response(request, response)
  File "/mnt/disk1/django/env_decorator/lib/python3.6/site-packages/django/contrib/redirects/middleware.py", line 29, in process_response
    current_site = get_current_site(request)
  File "/mnt/disk1/django/env_decorator/lib/python3.6/site-packages/django/contrib/sites/shortcuts.py", line 13, in get_current_site
    return Site.objects.get_current(request)
  File "/mnt/disk1/django/env_decorator/lib/python3.6/site-packages/django/contrib/sites/models.py", line 60, in get_current
    return self._get_site_by_request(request)
  File "/mnt/disk1/django/env_decorator/lib/python3.6/site-packages/django/contrib/sites/models.py", line 45, in _get_site_by_request
    SITE_CACHE[domain] = self.get(domain__iexact=domain)
  File "/mnt/disk1/django/env_decorator/lib/python3.6/site-packages/django/db/models/manager.py", line 85, in manager_method
    return getattr(self.get_queryset(), name)(*args, **kwargs)
  File "/mnt/disk1/django/env_decorator/lib/python3.6/site-packages/django/db/models/query.py", line 431, in get
    self.model._meta.object_name
django.contrib.sites.models.Site.DoesNotExist: Site matching query does not exist.
Internal Server Error: /admin/login/
Traceback (most recent call last):
  File "/mnt/disk1/django/env_decorator/lib/python3.6/site-packages/django/contrib/sites/models.py", line 39, in _get_site_by_request
    SITE_CACHE[host] = self.get(domain__iexact=host)
  File "/mnt/disk1/django/env_decorator/lib/python3.6/site-packages/django/db/models/manager.py", line 85, in manager_method
    return getattr(self.get_queryset(), name)(*args, **kwargs)
  File "/mnt/disk1/django/env_decorator/lib/python3.6/site-packages/django/db/models/query.py", line 431, in get
    self.model._meta.object_name
django.contrib.sites.models.Site.DoesNotExist: Site matching query does not exist.

During handling of the above exception, another exception occurred:

Traceback (most recent call last):
  File "/mnt/disk1/django/env_decorator/lib/python3.6/site-packages/django/core/handlers/exception.py", line 47, in inner
    response = get_response(request)
  File "/mnt/disk1/django/env_decorator/lib/python3.6/site-packages/django/core/handlers/base.py", line 181, in _get_response
    response = wrapped_callback(request, *callback_args, **callback_kwargs)
  File "/mnt/disk1/django/env_decorator/lib/python3.6/site-packages/django/views/decorators/cache.py", line 44, in _wrapped_view_func
    response = view_func(request, *args, **kwargs)
  File "/mnt/disk1/django/env_decorator/lib/python3.6/site-packages/django/contrib/admin/sites.py", line 410, in login
    return LoginView.as_view(**defaults)(request)
  File "/mnt/disk1/django/env_decorator/lib/python3.6/site-packages/django/views/generic/base.py", line 70, in view
    return self.dispatch(request, *args, **kwargs)
  File "/mnt/disk1/django/env_decorator/lib/python3.6/site-packages/django/utils/decorators.py", line 43, in _wrapper
    return bound_method(*args, **kwargs)
  File "/mnt/disk1/django/env_decorator/lib/python3.6/site-packages/django/views/decorators/debug.py", line 89, in sensitive_post_parameters_wrapper
    return view(request, *args, **kwargs)
  File "/mnt/disk1/django/env_decorator/lib/python3.6/site-packages/django/utils/decorators.py", line 43, in _wrapper
    return bound_method(*args, **kwargs)
  File "/mnt/disk1/django/env_decorator/lib/python3.6/site-packages/django/utils/decorators.py", line 130, in _wrapped_view
    response = view_func(request, *args, **kwargs)
  File "/mnt/disk1/django/env_decorator/lib/python3.6/site-packages/django/utils/decorators.py", line 43, in _wrapper
    return bound_method(*args, **kwargs)
  File "/mnt/disk1/django/env_decorator/lib/python3.6/site-packages/django/views/decorators/cache.py", line 44, in _wrapped_view_func
    response = view_func(request, *args, **kwargs)
  File "/mnt/disk1/django/env_decorator/lib/python3.6/site-packages/django/contrib/auth/views.py", line 63, in dispatch
    return super().dispatch(request, *args, **kwargs)
  File "/mnt/disk1/django/env_decorator/lib/python3.6/site-packages/django/views/generic/base.py", line 98, in dispatch
    return handler(request, *args, **kwargs)
  File "/mnt/disk1/django/env_decorator/lib/python3.6/site-packages/django/views/generic/edit.py", line 133, in get
    return self.render_to_response(self.get_context_data())
  File "/mnt/disk1/django/env_decorator/lib/python3.6/site-packages/django/contrib/auth/views.py", line 97, in get_context_data
    current_site = get_current_site(self.request)
  File "/mnt/disk1/django/env_decorator/lib/python3.6/site-packages/django/contrib/sites/shortcuts.py", line 13, in get_current_site
    return Site.objects.get_current(request)
  File "/mnt/disk1/django/env_decorator/lib/python3.6/site-packages/django/contrib/sites/models.py", line 60, in get_current
    return self._get_site_by_request(request)
  File "/mnt/disk1/django/env_decorator/lib/python3.6/site-packages/django/contrib/sites/models.py", line 45, in _get_site_by_request
    SITE_CACHE[domain] = self.get(domain__iexact=domain)
  File "/mnt/disk1/django/env_decorator/lib/python3.6/site-packages/django/db/models/manager.py", line 85, in manager_method
    return getattr(self.get_queryset(), name)(*args, **kwargs)
  File "/mnt/disk1/django/env_decorator/lib/python3.6/site-packages/django/db/models/query.py", line 431, in get
    self.model._meta.object_name
django.contrib.sites.models.Site.DoesNotExist: Site matching query does not exist.
Internal Server Error: /favicon.ico
Traceback (most recent call last):
  File "/mnt/disk1/django/env_decorator/lib/python3.6/site-packages/django/contrib/sites/models.py", line 39, in _get_site_by_request
    SITE_CACHE[host] = self.get(domain__iexact=host)
  File "/mnt/disk1/django/env_decorator/lib/python3.6/site-packages/django/db/models/manager.py", line 85, in manager_method
    return getattr(self.get_queryset(), name)(*args, **kwargs)
  File "/mnt/disk1/django/env_decorator/lib/python3.6/site-packages/django/db/models/query.py", line 431, in get
    self.model._meta.object_name
django.contrib.sites.models.Site.DoesNotExist: Site matching query does not exist.

During handling of the above exception, another exception occurred:

Traceback (most recent call last):
  File "/mnt/disk1/django/env_decorator/lib/python3.6/site-packages/django/core/handlers/exception.py", line 47, in inner
    response = get_response(request)
  File "/mnt/disk1/django/env_decorator/lib/python3.6/site-packages/django/utils/deprecation.py", line 116, in __call__
    response = self.process_response(request, response)
  File "/mnt/disk1/django/env_decorator/lib/python3.6/site-packages/django/contrib/redirects/middleware.py", line 29, in process_response
    current_site = get_current_site(request)
  File "/mnt/disk1/django/env_decorator/lib/python3.6/site-packages/django/contrib/sites/shortcuts.py", line 13, in get_current_site
    return Site.objects.get_current(request)
  File "/mnt/disk1/django/env_decorator/lib/python3.6/site-packages/django/contrib/sites/models.py", line 60, in get_current
    return self._get_site_by_request(request)
  File "/mnt/disk1/django/env_decorator/lib/python3.6/site-packages/django/contrib/sites/models.py", line 45, in _get_site_by_request
    SITE_CACHE[domain] = self.get(domain__iexact=domain)
  File "/mnt/disk1/django/env_decorator/lib/python3.6/site-packages/django/db/models/manager.py", line 85, in manager_method
    return getattr(self.get_queryset(), name)(*args, **kwargs)
  File "/mnt/disk1/django/env_decorator/lib/python3.6/site-packages/django/db/models/query.py", line 431, in get
    self.model._meta.object_name
django.contrib.sites.models.Site.DoesNotExist: Site matching query does not exist.
/mnt/disk1/django/decorator/decorator/settings.py changed, reloading.
Using selector: EpollSelector
Watching for file changes with StatReloader
Using selector: EpollSelector
Using selector: EpollSelector
Watching for file changes with StatReloader
/mnt/disk1/django/decorator/decorator/settings.py changed, reloading.
Using selector: EpollSelector
Watching for file changes with StatReloader
Using selector: EpollSelector
Using selector: EpollSelector
Using selector: EpollSelector
Watching for file changes with StatReloader
/mnt/disk1/django/decorator/decorator/settings.py changed, reloading.
Using selector: EpollSelector
Watching for file changes with StatReloader
Internal Server Error: /admin/login/
Traceback (most recent call last):
  File "/mnt/disk1/django/env_decorator/lib/python3.6/site-packages/django/contrib/sites/models.py", line 39, in _get_site_by_request
    SITE_CACHE[host] = self.get(domain__iexact=host)
  File "/mnt/disk1/django/env_decorator/lib/python3.6/site-packages/django/db/models/manager.py", line 85, in manager_method
    return getattr(self.get_queryset(), name)(*args, **kwargs)
  File "/mnt/disk1/django/env_decorator/lib/python3.6/site-packages/django/db/models/query.py", line 431, in get
    self.model._meta.object_name
django.contrib.sites.models.Site.DoesNotExist: Site matching query does not exist.

During handling of the above exception, another exception occurred:

Traceback (most recent call last):
  File "/mnt/disk1/django/env_decorator/lib/python3.6/site-packages/django/core/handlers/exception.py", line 47, in inner
    response = get_response(request)
  File "/mnt/disk1/django/env_decorator/lib/python3.6/site-packages/django/core/handlers/base.py", line 181, in _get_response
    response = wrapped_callback(request, *callback_args, **callback_kwargs)
  File "/mnt/disk1/django/env_decorator/lib/python3.6/site-packages/django/views/decorators/cache.py", line 44, in _wrapped_view_func
    response = view_func(request, *args, **kwargs)
  File "/mnt/disk1/django/env_decorator/lib/python3.6/site-packages/django/contrib/admin/sites.py", line 410, in login
    return LoginView.as_view(**defaults)(request)
  File "/mnt/disk1/django/env_decorator/lib/python3.6/site-packages/django/views/generic/base.py", line 70, in view
    return self.dispatch(request, *args, **kwargs)
  File "/mnt/disk1/django/env_decorator/lib/python3.6/site-packages/django/utils/decorators.py", line 43, in _wrapper
    return bound_method(*args, **kwargs)
  File "/mnt/disk1/django/env_decorator/lib/python3.6/site-packages/django/views/decorators/debug.py", line 89, in sensitive_post_parameters_wrapper
    return view(request, *args, **kwargs)
  File "/mnt/disk1/django/env_decorator/lib/python3.6/site-packages/django/utils/decorators.py", line 43, in _wrapper
    return bound_method(*args, **kwargs)
  File "/mnt/disk1/django/env_decorator/lib/python3.6/site-packages/django/utils/decorators.py", line 130, in _wrapped_view
    response = view_func(request, *args, **kwargs)
  File "/mnt/disk1/django/env_decorator/lib/python3.6/site-packages/django/utils/decorators.py", line 43, in _wrapper
    return bound_method(*args, **kwargs)
  File "/mnt/disk1/django/env_decorator/lib/python3.6/site-packages/django/views/decorators/cache.py", line 44, in _wrapped_view_func
    response = view_func(request, *args, **kwargs)
  File "/mnt/disk1/django/env_decorator/lib/python3.6/site-packages/django/contrib/auth/views.py", line 63, in dispatch
    return super().dispatch(request, *args, **kwargs)
  File "/mnt/disk1/django/env_decorator/lib/python3.6/site-packages/django/views/generic/base.py", line 98, in dispatch
    return handler(request, *args, **kwargs)
  File "/mnt/disk1/django/env_decorator/lib/python3.6/site-packages/django/views/generic/edit.py", line 133, in get
    return self.render_to_response(self.get_context_data())
  File "/mnt/disk1/django/env_decorator/lib/python3.6/site-packages/django/contrib/auth/views.py", line 97, in get_context_data
    current_site = get_current_site(self.request)
  File "/mnt/disk1/django/env_decorator/lib/python3.6/site-packages/django/contrib/sites/shortcuts.py", line 13, in get_current_site
    return Site.objects.get_current(request)
  File "/mnt/disk1/django/env_decorator/lib/python3.6/site-packages/django/contrib/sites/models.py", line 60, in get_current
    return self._get_site_by_request(request)
  File "/mnt/disk1/django/env_decorator/lib/python3.6/site-packages/django/contrib/sites/models.py", line 45, in _get_site_by_request
    SITE_CACHE[domain] = self.get(domain__iexact=domain)
  File "/mnt/disk1/django/env_decorator/lib/python3.6/site-packages/django/db/models/manager.py", line 85, in manager_method
    return getattr(self.get_queryset(), name)(*args, **kwargs)
  File "/mnt/disk1/django/env_decorator/lib/python3.6/site-packages/django/db/models/query.py", line 431, in get
    self.model._meta.object_name
django.contrib.sites.models.Site.DoesNotExist: Site matching query does not exist.
Internal Server Error: /favicon.ico
Traceback (most recent call last):
  File "/mnt/disk1/django/env_decorator/lib/python3.6/site-packages/django/contrib/sites/models.py", line 39, in _get_site_by_request
    SITE_CACHE[host] = self.get(domain__iexact=host)
  File "/mnt/disk1/django/env_decorator/lib/python3.6/site-packages/django/db/models/manager.py", line 85, in manager_method
    return getattr(self.get_queryset(), name)(*args, **kwargs)
  File "/mnt/disk1/django/env_decorator/lib/python3.6/site-packages/django/db/models/query.py", line 431, in get
    self.model._meta.object_name
django.contrib.sites.models.Site.DoesNotExist: Site matching query does not exist.

During handling of the above exception, another exception occurred:

Traceback (most recent call last):
  File "/mnt/disk1/django/env_decorator/lib/python3.6/site-packages/django/core/handlers/exception.py", line 47, in inner
    response = get_response(request)
  File "/mnt/disk1/django/env_decorator/lib/python3.6/site-packages/django/utils/deprecation.py", line 116, in __call__
    response = self.process_response(request, response)
  File "/mnt/disk1/django/env_decorator/lib/python3.6/site-packages/django/contrib/redirects/middleware.py", line 29, in process_response
    current_site = get_current_site(request)
  File "/mnt/disk1/django/env_decorator/lib/python3.6/site-packages/django/contrib/sites/shortcuts.py", line 13, in get_current_site
    return Site.objects.get_current(request)
  File "/mnt/disk1/django/env_decorator/lib/python3.6/site-packages/django/contrib/sites/models.py", line 60, in get_current
    return self._get_site_by_request(request)
  File "/mnt/disk1/django/env_decorator/lib/python3.6/site-packages/django/contrib/sites/models.py", line 45, in _get_site_by_request
    SITE_CACHE[domain] = self.get(domain__iexact=domain)
  File "/mnt/disk1/django/env_decorator/lib/python3.6/site-packages/django/db/models/manager.py", line 85, in manager_method
    return getattr(self.get_queryset(), name)(*args, **kwargs)
  File "/mnt/disk1/django/env_decorator/lib/python3.6/site-packages/django/db/models/query.py", line 431, in get
    self.model._meta.object_name
django.contrib.sites.models.Site.DoesNotExist: Site matching query does not exist.
Using selector: EpollSelector
Using selector: EpollSelector
Using selector: EpollSelector
Watching for file changes with StatReloader
Not Found: /favicon.ico
Not Found: /favicon.ico
Not Found: /favicon.ico
/mnt/disk1/django/decorator/main/views.py changed, reloading.
Using selector: EpollSelector
Watching for file changes with StatReloader
/mnt/disk1/django/decorator/main/views.py changed, reloading.
Using selector: EpollSelector
Watching for file changes with StatReloader
Internal Server Error: /
Traceback (most recent call last):
  File "/mnt/disk1/django/env_decorator/lib/python3.6/site-packages/django/core/handlers/exception.py", line 47, in inner
    response = get_response(request)
  File "/mnt/disk1/django/env_decorator/lib/python3.6/site-packages/django/core/handlers/base.py", line 181, in _get_response
    response = wrapped_callback(request, *callback_args, **callback_kwargs)
  File "/mnt/disk1/django/decorator/main/views.py", line 57, in index
    textpage_data, template = render_textpage(request, "index", TextPage)
  File "/mnt/disk1/django/decorator/main/views.py", line 37, in render_textpage
    default_context_d = default_context(request)
  File "/mnt/disk1/django/decorator/main/views.py", line 30, in default_context
    docs = list(TextPage.objects.filter(is_docs=True))
  File "/mnt/disk1/django/env_decorator/lib/python3.6/site-packages/django/db/models/manager.py", line 85, in manager_method
    return getattr(self.get_queryset(), name)(*args, **kwargs)
  File "/mnt/disk1/django/env_decorator/lib/python3.6/site-packages/django/db/models/query.py", line 942, in filter
    return self._filter_or_exclude(False, *args, **kwargs)
  File "/mnt/disk1/django/env_decorator/lib/python3.6/site-packages/django/db/models/query.py", line 962, in _filter_or_exclude
    clone._filter_or_exclude_inplace(negate, *args, **kwargs)
  File "/mnt/disk1/django/env_decorator/lib/python3.6/site-packages/django/db/models/query.py", line 969, in _filter_or_exclude_inplace
    self._query.add_q(Q(*args, **kwargs))
  File "/mnt/disk1/django/env_decorator/lib/python3.6/site-packages/django/db/models/sql/query.py", line 1358, in add_q
    clause, _ = self._add_q(q_object, self.used_aliases)
  File "/mnt/disk1/django/env_decorator/lib/python3.6/site-packages/django/db/models/sql/query.py", line 1380, in _add_q
    split_subq=split_subq, check_filterable=check_filterable,
  File "/mnt/disk1/django/env_decorator/lib/python3.6/site-packages/django/db/models/sql/query.py", line 1258, in build_filter
    lookups, parts, reffed_expression = self.solve_lookup_type(arg)
  File "/mnt/disk1/django/env_decorator/lib/python3.6/site-packages/django/db/models/sql/query.py", line 1084, in solve_lookup_type
    _, field, _, lookup_parts = self.names_to_path(lookup_splitted, self.get_meta())
  File "/mnt/disk1/django/env_decorator/lib/python3.6/site-packages/django/db/models/sql/query.py", line 1482, in names_to_path
    "Choices are: %s" % (name, ", ".join(available)))
django.core.exceptions.FieldError: Cannot resolve keyword 'is_docs' into field. Choices are: alias, canonical, content, id, img_path, is_service, lastmod, menuposition, menushow, menutitle, name, og_description, og_title, og_type, og_type_author, og_type_pb_time, seo_description, seo_h1, seo_keywords, seo_title, sitemap
Internal Server Error: /
Traceback (most recent call last):
  File "/mnt/disk1/django/env_decorator/lib/python3.6/site-packages/django/core/handlers/exception.py", line 47, in inner
    response = get_response(request)
  File "/mnt/disk1/django/env_decorator/lib/python3.6/site-packages/django/core/handlers/base.py", line 181, in _get_response
    response = wrapped_callback(request, *callback_args, **callback_kwargs)
  File "/mnt/disk1/django/decorator/main/views.py", line 57, in index
    textpage_data, template = render_textpage(request, "index", TextPage)
  File "/mnt/disk1/django/decorator/main/views.py", line 37, in render_textpage
    default_context_d = default_context(request)
  File "/mnt/disk1/django/decorator/main/views.py", line 30, in default_context
    docs = list(TextPage.objects.filter(is_docs=True))
  File "/mnt/disk1/django/env_decorator/lib/python3.6/site-packages/django/db/models/manager.py", line 85, in manager_method
    return getattr(self.get_queryset(), name)(*args, **kwargs)
  File "/mnt/disk1/django/env_decorator/lib/python3.6/site-packages/django/db/models/query.py", line 942, in filter
    return self._filter_or_exclude(False, *args, **kwargs)
  File "/mnt/disk1/django/env_decorator/lib/python3.6/site-packages/django/db/models/query.py", line 962, in _filter_or_exclude
    clone._filter_or_exclude_inplace(negate, *args, **kwargs)
  File "/mnt/disk1/django/env_decorator/lib/python3.6/site-packages/django/db/models/query.py", line 969, in _filter_or_exclude_inplace
    self._query.add_q(Q(*args, **kwargs))
  File "/mnt/disk1/django/env_decorator/lib/python3.6/site-packages/django/db/models/sql/query.py", line 1358, in add_q
    clause, _ = self._add_q(q_object, self.used_aliases)
  File "/mnt/disk1/django/env_decorator/lib/python3.6/site-packages/django/db/models/sql/query.py", line 1380, in _add_q
    split_subq=split_subq, check_filterable=check_filterable,
  File "/mnt/disk1/django/env_decorator/lib/python3.6/site-packages/django/db/models/sql/query.py", line 1258, in build_filter
    lookups, parts, reffed_expression = self.solve_lookup_type(arg)
  File "/mnt/disk1/django/env_decorator/lib/python3.6/site-packages/django/db/models/sql/query.py", line 1084, in solve_lookup_type
    _, field, _, lookup_parts = self.names_to_path(lookup_splitted, self.get_meta())
  File "/mnt/disk1/django/env_decorator/lib/python3.6/site-packages/django/db/models/sql/query.py", line 1482, in names_to_path
    "Choices are: %s" % (name, ", ".join(available)))
django.core.exceptions.FieldError: Cannot resolve keyword 'is_docs' into field. Choices are: alias, canonical, content, id, img_path, is_service, lastmod, menuposition, menushow, menutitle, name, og_description, og_title, og_type, og_type_author, og_type_pb_time, seo_description, seo_h1, seo_keywords, seo_title, sitemap
/mnt/disk1/django/decorator/main/views.py changed, reloading.
Using selector: EpollSelector
Watching for file changes with StatReloader
/mnt/disk1/django/decorator/decorator/settings.py changed, reloading.
